Workbook

Sheet db
A1: students
A2: id | B2: nis | C2: nisn | D2: name
A4: levels
A5: id | B5: level_name
A7: classes
A8: id | B8: level_id | C8: class_name
A10: history_student
A11: id | B11: student_id | C11: class_id | D11: tahun_pelajaran | E11: semester | F11: class_advisor_id | G11: status | H11: is_lulus | I11: is_naik
A13: subjects
A14: id | B14: subject_name
A16: assessment
A17: id | B17: history_id | C17: subject_id | D17: numeric_grade | E17: letter_grade | F17: grade_type | G17: class_advisor_note | H17: competency_achievement | I17: absence_id
A19: absence
A20: id | B20: history_id | C20: sakit | D20: izin | E20: alpa
A22: teachers
A23: id | B23: teacher_name | C23: teacher_title

Sheet API & Feature
A1: DB | B1: post | C1: get all | D1: get by id | E1: put | F1: patch | G1: delete
A2: =db!A1 -> students | B2: nis:123, nisn:1233, name:""
A3: =db!A4 -> levels | B3: level_name: "X"
A4: =db!A7 -> classes | B4: level_id: 1, class_name: "TP"
A5: =db!A10 -> history_student | B5: student_id: 1, tahun_pelajaran:"2025/2026", class_id: 1, semester: 5, wali_kelas_id: 1
A6: =db!A13 -> subjects | B6: subject_name: "Matematika"
A7: =db!A16 -> assessment | B7: history_student_id: 1, subject_id: 1, grade: 80
A8: =db!A19 -> absence | B8: history_student_id: 1, sakit: 20, izin: 2, alpa: 3
A9: =db!A22 -> teachers | B9: teacher_name: "Ken",
A10: =db!A25 -> 0
A15: Feature | B15: post | C15: get all | D15: get by id | E15: put | F15: patch | G15: delete | H15: status
A16: =A1 -> DB
A17: =A2 -> students
A18: =A3 -> levels
A19: =A4 -> classes
A20: =A5 -> history_student
A21: =A6 -> subjects
A22: =A7 -> assessment
A23: =A8 -> absence
A24: =A9 -> teachers
A26: Feature | B26: details | C26: db | D26: status
A27: deteksi nilai < 70 | B27: cari nilai yang belum tuntas. Yang < 70 | C27: assessment
A28: gabung semua data di rapor | B28: ambil data di db dan ditampilkan pada rapor
A29: [frontend] upload data nilai | B29: buat page frontend
A30: [frontend] upload data siswa | B30: buat page frontend
A31: [frontend] upload data guru | B31: buat page frontend
A32: [frontend] tampilkan semua data nilai | B32: tampilkan semua data nilai dan tandai nilai yang belum tuntas
A33: [backend] join table assessment | C33: assessment, history_student teacher
A34: [frontend] filter tidak tuntas | B34: tampilkan yang tidak tuntas saja
A35: [backend] buat seeds file
A36: [backend] get by hiwtory student
A37: [db] FK diberi notNullable() ?

Sheet 1
A1: level_name | B1: id
A2: X | B2: 1
A3: XI | B3: 2
A4: XII | B4: 3

Sheet 6
A1: id | B1: level_id | C1: class_name | F1: no | G1: tingkat | H1: kelas
A2: 1 | B2: 3 | C2: TKJ 1 | D2: 1 | F2: 1 | G2: XII | H2: TKJ 1 | I2: =_xlfn.CONCAT(G2," ",H2) -> XII TKJ 1 | J2: 1
A3: 2 | B3: 3 | C3: TOI 1 | D3: 2 | F3: 2 | G3: XII | H3: TOI 1 | I3: =_xlfn.CONCAT(G3," ",H3) -> XII TOI 1 | J3: 2
A4: 3 | B4: 3 | C4: TOI 2 | D4: 3 | F4: 3 | G4: XII | H4: TOI 2 | I4: =_xlfn.CONCAT(G4," ",H4) -> XII TOI 2 | J4: 3
A5: 4 | B5: 3 | C5: TP 1 | D5: 4 | F5: 4 | G5: XII | H5: TP 1 | I5: =_xlfn.CONCAT(G5," ",H5) -> XII TP 1 | J5: 4
A6: 5 | B6: 3 | C6: TP 2 | D6: 5 | F6: 5 | G6: XII | H6: TP 2 | I6: =_xlfn.CONCAT(G6," ",H6) -> XII TP 2 | J6: 5
A7: 6 | B7: 3 | C7: TP 3 | D7: 6 | F7: 6 | G7: XII | H7: TP 3 | I7: =_xlfn.CONCAT(G7," ",H7) -> XII TP 3 | J7: 6
A8: 7 | B8: 3 | C8: TP 4 | D8: 7 | F8: 7 | G8: XII | H8: TP 4 | I8: =_xlfn.CONCAT(G8," ",H8) -> XII TP 4 | J8: 7
A9: 8 | B9: 3 | C9: TSM 1 | D9: 8 | F9: 8 | G9: XII | H9: TSM 1 | I9: =_xlfn.CONCAT(G9," ",H9) -> XII TSM 1 | J9: 8
A10: 9 | B10: 3 | C10: TSM 2 | D10: 9 | F10: 9 | G10: XII | H10: TSM 2 | I10: =_xlfn.CONCAT(G10," ",H10) -> XII TSM 2 | J10: 9
A11: 10 | B11: =VLOOKUP(G11,'1'!$A$2:$B$4,2,FALSE) -> 1 | C11: =H11 -> TJKT 1 | F11: 10 | G11: X | H11: TJKT 1 | I11: =_xlfn.CONCAT(G11," ",H11) -> X TJKT 1 | J11: 10
A12: 11 | B12: =VLOOKUP(G12,'1'!$A$2:$B$4,2,FALSE) -> 1 | C12: =H12 -> TJKT 2 | F12: 11 | G12: X | H12: TJKT 2 | I12: =_xlfn.CONCAT(G12," ",H12) -> X TJKT 2 | J12: 11
A13: 12 | B13: =VLOOKUP(G13,'1'!$A$2:$B$4,2,FALSE) -> 1 | C13: =H13 -> TOI 1 | F13: 12 | G13: X | H13: TOI 1 | I13: =_xlfn.CONCAT(G13," ",H13) -> X TOI 1 | J13: 12
A14: 13 | B14: =VLOOKUP(G14,'1'!$A$2:$B$4,2,FALSE) -> 1 | C14: =H14 -> TOI 2 | F14: 13 | G14: X | H14: TOI 2 | I14: =_xlfn.CONCAT(G14," ",H14) -> X TOI 2 | J14: 13
A15: 14 | B15: =VLOOKUP(G15,'1'!$A$2:$B$4,2,FALSE) -> 1 | C15: =H15 -> TOI 3 | F15: 14 | G15: X | H15: TOI 3 | I15: =_xlfn.CONCAT(G15," ",H15) -> X TOI 3 | J15: 14
A16: 15 | B16: =VLOOKUP(G16,'1'!$A$2:$B$4,2,FALSE) -> 1 | C16: =H16 -> TP 1 | F16: 15 | G16: X | H16: TP 1 | I16: =_xlfn.CONCAT(G16," ",H16) -> X TP 1 | J16: 15
A17: 16 | B17: =VLOOKUP(G17,'1'!$A$2:$B$4,2,FALSE) -> 1 | C17: =H17 -> TP 2 | F17: 16 | G17: X | H17: TP 2 | I17: =_xlfn.CONCAT(G17," ",H17) -> X TP 2 | J17: 16
A18: 17 | B18: =VLOOKUP(G18,'1'!$A$2:$B$4,2,FALSE) -> 1 | C18: =H18 -> TP 3 | F18: 17 | G18: X | H18: TP 3 | I18: =_xlfn.CONCAT(G18," ",H18) -> X TP 3 | J18: 17
A19: 18 | B19: =VLOOKUP(G19,'1'!$A$2:$B$4,2,FALSE) -> 1 | C19: =H19 -> TP 4 | F19: 18 | G19: X | H19: TP 4 | I19: =_xlfn.CONCAT(G19," ",H19) -> X TP 4 | J19: 18
A20: 19 | B20: =VLOOKUP(G20,'1'!$A$2:$B$4,2,FALSE) -> 1 | C20: =H20 -> TP 5 | F20: 19 | G20: X | H20: TP 5 | I20: =_xlfn.CONCAT(G20," ",H20) -> X TP 5 | J20: 19
A21: 20 | B21: =VLOOKUP(G21,'1'!$A$2:$B$4,2,FALSE) -> 1 | C21: =H21 -> TSM 1 | F21: 20 | G21: X | H21: TSM 1 | I21: =_xlfn.CONCAT(G21," ",H21) -> X TSM 1 | J21: 20
A22: 21 | B22: =VLOOKUP(G22,'1'!$A$2:$B$4,2,FALSE) -> 1 | C22: =H22 -> TSM 2 | F22: 21 | G22: X | H22: TSM 2 | I22: =_xlfn.CONCAT(G22," ",H22) -> X TSM 2 | J22: 21
... A33: 32 | B33: =VLOOKUP(G33,'1'!$A$2:$B$4,2,FALSE) -> 2 | C33: =H33 -> TSM 2 | F33: 32 | G33: XI | H33: TSM 2 | I33: =_xlfn.CONCAT(G33," ",H33) -> XI TSM 2 | J33: 32

Sheet 2
A1: id | B1: subject_name | D1: subject_type | F1: kelas 12 | G1: umum | H1: 1 | I1: 2 | J1: 3 | K1: 4 | L1: 12 | M1: 26 | N1: 5 | O1: 6 | U1: gabung | X1: 1,2,3,4,12,26,5,6
A2: 1 | B2: Pendidikan Agama Islam dan Budi Pekerti | C2: =A2 -> 1 | D2: umum | G2: tkj | H2: 13 | I2: 14 | J2: 15 | K2: 18 | L2: 20 | X2: 13,14,15,18,20
A3: 2 | B3: Pendidikan Agama Hindu dan Budi Pekerti | C3: =A3 -> 2 | D3: umum | G3: tp | H3: 13 | I3: 14 | J3: 15 | K3: 16 | L3: 22 | X3: 13,14,15,16,22
A4: 3 | B4: Pendidikan Agama Kristen dan Budi Pekerti | C4: =A4 -> 3 | D4: umum | G4: tsm | H4: 13 | I4: 14 | J4: 15 | K4: 19 | L4: 23 | X4: 13,14,15,19,23
A5: 4 | B5: Pendidikan Pancasila | C5: =A5 -> 4 | D5: umum | G5: toi | H5: 13 | I5: 14 | J5: 15 | K5: 17 | L5: 21 | X5: 13,14,15,17,21
A6: 5 | B6: Sejarah | C6: =A6 -> 5 | D6: umum
A7: 6 | B7: Seni Budaya | C7: =A7 -> 6 | D7: umum | F7: kelas 10 | G7: UMUM | H7: 1 | I7: 2 | J7: 3 | K7: 33 | L7: 4 | M7: 12 | N7: 26 | O7: 5 | P7: 6 | Q7: 27 | T7: =_xlfn.CONCAT(G7,":[") -> UMUM:[ | U7: =_xlfn.TEXTJOIN(",",TRUE,H7:Q7) -> 1,2,3,33,4,12,26,5,6,27
A8: 7 | B8: Dasar-dasar Teknik Pemesinan | C8: =A8 -> 7 | D8: kejuruan | G8: TKJ | H8: 13 | I8: 14 | J8: 28 | K8: 29 | L8: 9 | T8: =_xlfn.CONCAT(G8,":[") -> TKJ:[ | U8: =_xlfn.TEXTJOIN(",",TRUE,H8:P8) -> 13,14,28,29,9 | X8: Karena semester 6 pada jenjang SMK umumnya berfokus pada pemantapan, ujian sekolah, kelulusan, atau kelanjutan dari Praktik Kerja Lapangan (PKL), capaian kompetensi di bawah ini disusun menggunakan kata kerja operasional yang menggambarkan pencapaian optimal maupun area yang perlu bimbingan.
A9: 8 | B9: Dasar-dasar Teknik Otomasi Industri | C9: =A9 -> 8 | D9: kejuruan | G9: TP | H9: 13 | I9: 14 | J9: 28 | K9: 29 | L9: 7 | T9: =_xlfn.CONCAT(G9,":[") -> TP:[ | U9: =_xlfn.TEXTJOIN(",",TRUE,H9:P9) -> 13,14,28,29,7
A10: 9 | B10: Dasar-dasar Teknik Komputer dan Jaringan | C10: =A10 -> 9 | D10: kejuruan | G10: TSM | H10: 13 | I10: 14 | J10: 28 | K10: 29 | L10: 10 | T10: =_xlfn.CONCAT(G10,":[") -> TSM:[ | U10: =_xlfn.TEXTJOIN(",",TRUE,H10:P10) -> 13,14,28,29,10 | X10: 1. Pendidikan Agama Islam dan Budi Pekerti
A11: 10 | B11: Dasar-dasar Teknik Sepeda Motor | C11: =A11 -> 10 | D11: kejuruan | G11: TOI | H11: 13 | I11: 14 | J11: 28 | K11: 29 | L11: 8 | T11: =_xlfn.CONCAT(G11,":[") -> TOI:[ | U11: =_xlfn.TEXTJOIN(",",TRUE,H11:P11) -> 13,14,28,29,8 | X11: Menunjukkan penguasaan yang sangat baik dalam: menganalisis dan mengevaluasi ketentuan pernikahan dalam Islam, ketentuan waris (faraidh), serta konsisten dalam menyebarkan dakwah Islam secara damai dan menunjukkan perilaku mulia (budi pekerti) dalam kehidupan sehari-hari.
A12: 11 | B12: Muatan Lokal Bahasa Daerah | C12: =A12 -> 11 | D12: mulok | G12: mulok | H12: 11 | T12: =_xlfn.CONCAT(G12,"=[") -> mulok=[
A13: 12 | B13: Bahasa Indonesia | C13: =A13 -> 12 | D13: umum | X13: Perlu bimbingan dalam: memahami lebih mendalam mengenai perhitungan pembagian harta waris secara tepat sesuai dengan syariat Islam.
A14: 13 | B14: Matematika (Umum) | C14: =A14 -> 13 | D14: kejuruan | F14: kelas 11 | G14: UMUM | H14: 1 | I14: 2 | J14: 3 | K14: 33 | L14: 4 | M14: 12 | N14: 26 | O14: 5 | T14: =_xlfn.CONCAT(G14,":[") -> UMUM:[ | U14: =_xlfn.TEXTJOIN(",",TRUE,H14:P14) -> 1,2,3,33,4,12,26,5
A15: 14 | B15: Bahasa Inggris | C15: =A15 -> 14 | D15: kejuruan | G15: TKJ | H15: 13 | I15: 14 | J15: 18 | K15: 30 | L15: 20 | T15: =_xlfn.CONCAT(G15,":[") -> TKJ:[ | U15: =_xlfn.TEXTJOIN(",",TRUE,H15:P15) -> 13,14,18,30,20 | X15: 2. Pendidikan Pancasila
A16: 15 | B16: Produk Kreatif dan Kewirausahaan | C16: =A16 -> 15 | D16: kejuruan | G16: TP | H16: 13 | I16: 14 | J16: 16 | K16: 30 | L16: 31 | T16: =_xlfn.CONCAT(G16,":[") -> TP:[ | U16: =_xlfn.TEXTJOIN(",",TRUE,H16:P16) -> 13,14,16,30,31 | X16: Menunjukkan penguasaan yang sangat baik dalam: menganalisis peluang dan tantangan penerapan Pancasila dalam kehidupan global, serta menunjukkan komitmen aktif dalam merawat kebinikaan, kesadaran hukum, dan bela negara sebagai warga negara yang baik.
A17: 16 | B17: Konsentrasi Keahlian Teknik Pemesinan | C17: =A17 -> 16 | D17: kejuruan | G17: TSM | H17: 13 | I17: 14 | J17: 19 | K17: 30 | L17: 23 | T17: =_xlfn.CONCAT(G17,":[") -> TSM:[ | U17: =_xlfn.TEXTJOIN(",",TRUE,H17:P17) -> 13,14,19,30,23
A18: 17 | B18: Konsentrasi Keahlian Teknik Otomasi Industri | C18: =A18 -> 17 | D18: kejuruan | G18: TOI | H18: 13 | I18: 14 | J18: 17 | K18: 30 | L18: 32 | T18: =_xlfn.CONCAT(G18,":[") -> TOI:[ | U18: =_xlfn.TEXTJOIN(",",TRUE,H18:P18) -> 13,14,17,30,32 | X18: Perlu bimbingan dalam: mengidentifikasi strategi solutif dalam mengatasi pelanggaran hak dan pengingkaran kewajiban warga negara di lingkungan sekitar.
A19: 18 | B19: Konsentrasi Keahlian Teknik Komputer dan Jaringan | C19: =A19 -> 18 | D19: kejuruan | G19: mulok | H19: 11
A20: 19 | B20: Konsentrasi Keahlian Teknik Sepeda Motor | C20: =A20 -> 19 | D20: kejuruan | X20: 3. Bahasa Indonesia
A21: 20 | B21: Sistem Perancangan IoT | C21: =A21 -> 20 | D21: kejuruan | X21: Menunjukkan penguasaan yang sangat baik dalam: menyusun, mengevaluasi, dan menyajikan dokumen lamaran pekerjaan, kritik, esai, serta artikel ilmiah populer dengan menggunakan struktur dan kebahasaan yang baik, benar, dan persuasif.
A22: 21 | B22: Gambar MEP | C22: =A22 -> 21 | D22: kejuruan
A23: 22 | B23: Pemrograman CNC | C23: =A23 -> 22 | D23: kejuruan | X23: Perlu bimbingan dalam: menyunting variasi kosakata formal dan struktur kalimat efektif saat menyusun esai atau artikel formal.
A24: 23 | B24: Gambar Teknik Manufaktur | C24: =A24 -> 23 | D24: kejuruan
A25: 24 | B25: Kursus Bahasa Asing | C25: =A25 -> 24 | D25: ekstra | X25: 4. Matematika (Umum)
A26: 25 | B26: Pramuka | C26: =A26 -> 25 | D26: ekstra | X26: Menunjukkan penguasaan yang sangat baik dalam: menganalisis, menginterpretasi, dan menyajikan data statistika (ukuran pemusatan dan penyebaran data) serta menentukan peluang suatu kejadian untuk memecahkan masalah kontekstual.
A27: 26 | B27: Pendidikan Jasmani, Olahraga, dan Kesehatan | C27: =A27 -> 26 | D27: umum
A28: 27 | B28: Koding dan Kecerdasan Artifisial | C28: =A28 -> 27 | D28: umum | X28: Perlu bimbingan dalam: menghitung nilai simpangan baku dan varians pada data kelompok secara akurat.
A29: 28 | B29: Informatika | C29: =A29 -> 28 | D29: kejuruan
A30: 29 | B30: Projek IPAS | C30: =A30 -> 29 | D30: kejuruan | X30: 5. Bahasa Inggris
A31: 30 | B31: Projek Kreatif dan Kewirausahaan | C31: =A31 -> 30 | D31: kejuruan | F31: Dasar Kejuruan 1 | G31: kejuruan | X31: Menunjukkan penguasaan yang sangat baik dalam: memahami, menganalisis, dan menyusun teks fungsional lisan dan tulis berbentuk report text, surat lamaran kerja (application letter), serta simulasi wawancara kerja (job interview) dengan lancar dan percaya diri.
A32: 31 | B32: Gambar Teknik Mesin | C32: =A32 -> 31 | D32: kejuruan | F32: Dasar Kejuruan 2 | G32: kejuruan
A33: 32 | B33: Pemrograman Sistem Robot Manipulator | C33: =A33 -> 32 | D33: kejuruan | F33: Dasar Kejuruan 3 | G33: kejuruan | X33: Perlu bimbingan dalam: merespons pertanyaan spontan menggunakan struktur kebahasaan (grammar) yang tepat saat simulasi wawancara kerja.
A34: 33 | B34: Pendidikan Agama Katholik dan Budi Pekerti | C34: =A34 -> 33 | D34: umum | F34: Dasar Kejuruan 4 | G34: kejuruan
A35: 34 | C35: =A35 -> 34 | F35: Konsentrasi Keahlian 1 | G35: kejuruan | X35: 6. Projek Kreatif dan Kewirausahaan (PKK)
A36: 35 | C36: =A36 -> 35 | F36: Konsentrasi Keahlian 2 | G36: kejuruan | X36: Menunjukkan penguasaan yang sangat baik dalam: menyusun laporan keuangan sederhana, mengevaluasi keberhasilan usaha, membuat strategi pemasaran digital (digital marketing), serta merencanakan keberlanjutan bisnis/wirausaha mandiri secara kreatif.
A37: 36 | C37: =A37 -> 36 | F37: Konsentrasi Keahlian 3 | G37: kejuruan
A38: 37 | C38: =A38 -> 37 | F38: Konsentrasi Keahlian 4 | G38: kejuruan | X38: Perlu bimbingan dalam: menghitung rasio profitabilitas dan titik impas (Break-Even Point) secara lebih teliti untuk evaluasi usaha.
A39: 38 | C39: =A39 -> 38 | F39: Konsentrasi Keahlian 5 | G39: kejuruan
X40: 8. Muatan Lokal Bahasa Daerah
...

Sheet 3
A1: id | B1: subject_id | C1: competency_achievement | D1: school_year | E1: semester | F1: id | H1: subject_id | I1: subject | J1: semester | K1: kelas | L1: achievement id | N1: id | O1: subject_id | P1: competency_achievement | Q1: school_year | R1: semester
A2: 1 | B2: 1 | C2: Menguasai hukum nikah dan waris Islam, konsisten berdakwah secara damai, serta selalu menerapkan budi pekerti mulia dalam kehidupan sehari-hari dengan sangat baik. | D2: 2025/2026 | E2: 6 | F2: =A2 -> 1 | H2: =B29 -> 1 | I2: =VLOOKUP(B29,'2'!$A$2:$B$39,2,FALSE) -> Pendidikan Agama Islam dan Budi Pekerti | J2: 2 | K2: X | L2: =A29 -> 28
A3: 2 | B3: 2 | C3: Menguasai konsep Tri Hita Karana & Tat Twam Asi untuk harmoni sosial, memahami ajaran Moksa sebagai tujuan tertinggi, serta konsisten menerapkan perilaku susila berlandaskan Dharma dalam kehidupan dan kerja. | D3: 2025/2026 | E3: 6 | F3: =A3 -> 2 | H3: =B30 -> 2 | I3: =VLOOKUP(B30,'2'!$A$2:$B$39,2,FALSE) -> Pendidikan Agama Hindu dan Budi Pekerti | J3: 2 | K3: X | L3: =A30 -> 29
A4: 3 | B4: 3 | C4: Menunjukkan penguasaan yang sangat baik dalam: menganalisis peran remaja Kristen dalam mewujudkan perdamaian, keadilan, dan kesetaraan di tengah masyarakat majemuk, serta mengevaluasi gaya hidup modern yang sesuai dengan nilai-nilai Kristiani sebagai wujud kedewasaan iman. | D4: 2025/2026 | E4: 6 | F4: =A4 -> 3 | H4: =B31 -> 3 | I4: =VLOOKUP(B31,'2'!$A$2:$B$39,2,FALSE) -> Pendidikan Agama Kristen dan Budi Pekerti | J4: 2 | K4: X | L4: =A31 -> 30
A5: 4 | B5: 4 | C5: Mampu menganalisis peluang serta tantangan Pancasila di era global, sekaligus menunjukkan komitmen nyata dalam merawat kebhinekaan, mematuhi hukum, dan membela negara sebagai warga negara yang bertanggung jawab. | D5: 2025/2026 | E5: 6 | F5: =A5 -> 4 | H5: =B32 -> 33 | I5: =VLOOKUP(B32,'2'!$A$2:$B$39,2,FALSE) -> Pendidikan Agama Katholik dan Budi Pekerti | J5: 2 | K5: X | L5: =A32 -> 31
A6: 5 | B6: 5 | D6: 2025/2026 | E6: 6 | F6: =A6 -> 5 | H6: =B33 -> 4 | I6: =VLOOKUP(B33,'2'!$A$2:$B$39,2,FALSE) -> Pendidikan Pancasila | J6: 2 | K6: X | L6: =A33 -> 32
A7: 6 | B7: 6 | D7: 2025/2026 | E7: 6 | F7: =A7 -> 6 | H7: =B34 -> 12 | I7: =VLOOKUP(B34,'2'!$A$2:$B$39,2,FALSE) -> Bahasa Indonesia | J7: 2 | K7: X | L7: =A34 -> 33
A8: 7 | B8: 7 | D8: 2025/2026 | E8: 6 | F8: =A8 -> 7 | H8: =B35 -> 26 | I8: =VLOOKUP(B35,'2'!$A$2:$B$39,2,FALSE) -> Pendidikan Jasmani, Olahraga, dan Kesehatan | J8: 2 | K8: X | L8: =A35 -> 34
A9: 8 | B9: 8 | D9: 2025/2026 | E9: 6 | F9: =A9 -> 8 | H9: =B36 -> 5 | I9: =VLOOKUP(B36,'2'!$A$2:$B$39,2,FALSE) -> Sejarah | J9: 2 | K9: X | L9: =A36 -> 35
A10: 9 | B10: 9 | D10: 2025/2026 | E10: 6 | F10: =A10 -> 9 | H10: =B37 -> 6 | I10: =VLOOKUP(B37,'2'!$A$2:$B$39,2,FALSE) -> Seni Budaya | J10: 2 | K10: X | L10: =A37 -> 36
A11: 10 | B11: 10 | D11: 2025/2026 | E11: 6 | F11: =A11 -> 10 | H11: =B38 -> 27 | I11: =VLOOKUP(B38,'2'!$A$2:$B$39,2,FALSE) -> Koding dan Kecerdasan Artifisial | J11: 2 | K11: X | L11: =A38 -> 37
A12: 11 | B12: 11 | C12: Mampu menerapkan tata krama bahasa daerah (unggah-ungguh) dalam berkomunikasi sehari-hari, serta mampu mengapresiasi dan mempraktikkan seni pertunjukan atau sastra daerah dengan laras dan leres. | D12: 2025/2026 | E12: 6 | F12: =A12 -> 11 | H12: =B39 -> 13 | I12: =VLOOKUP(B39,'2'!$A$2:$B$39,2,FALSE) -> Matematika (Umum) | J12: 2 | K12: X | L12: =A39 -> 38
A13: 12 | B13: 12 | C13: Mampu menyusun, mengevaluasi, dan menyajikan dokumen lamaran kerja, kritik, esai, serta artikel ilmiah populer dengan struktur dan kebahasaan yang baik, benar, dan persuasif. | D13: 2025/2026 | E13: 6 | F13: =A13 -> 12 | H13: =B40 -> 14 | I13: =VLOOKUP(B40,'2'!$A$2:$B$39,2,FALSE) -> Bahasa Inggris | J13: 2 | K13: X | L13: =A40 -> 39
A14: 13 | B14: 13 | C14: Mampu menganalisis, menginterpretasi, dan menyajikan data statistika (ukuran pemusatan dan penyebaran data) serta menghitung peluang suatu kejadian guna menyelesaikan permasalahan kontekstual. | D14: 2025/2026 | E14: 6 | F14: =A14 -> 13 | H14: =B41 -> 28 | I14: =VLOOKUP(B41,'2'!$A$2:$B$39,2,FALSE) -> Informatika | J14: 2 | K14: X | L14: =A41 -> 40
A15: 14 | B15: 14 | C15: Mampu memahami, menganalisis, dan menyusun teks fungsional (report text, surat lamaran kerja), serta melaksanakan simulasi wawancara kerja dengan lancar dan percaya diri. | D15: 2025/2026 | E15: 6 | F15: =A15 -> 14 | H15: =B42 -> 29 | I15: =VLOOKUP(B42,'2'!$A$2:$B$39,2,FALSE) -> Projek IPAS | J15: 2 | K15: X | L15: =A42 -> 41
A16: 15 | B16: 15 | C16: Mampu menyusun laporan keuangan sederhana, mengevaluasi kinerja usaha, menerapkan strategi pemasaran digital, serta merencanakan pengembangan wirausaha mandiri secara kreatif. | D16: 2025/2026 | E16: 6 | F16: =A16 -> 15 | H16: =B43 -> 9 | I16: =VLOOKUP(B43,'2'!$A$2:$B$39,2,FALSE) -> Dasar-dasar Teknik Komputer dan Jaringan | J16: 2 | K16: X | L16: =A43 -> 42
A17: 16 | B17: 16 | C17: Mampu merancang dan mengeksekusi proses bubut kompleks serta pengefraisan komponen presisi. Selain itu, terampil dalam memprogram dan mengoperasikan mesin CNC (bubut/frais) sesuai gambar kerja dan standar toleransi geometris yang ketat. | D17: 2025/2026 | E17: 6 | F17: =A17 -> 16 | H17: =B44 -> 7 | I17: =VLOOKUP(B44,'2'!$A$2:$B$39,2,FALSE) -> Dasar-dasar Teknik Pemesinan | J17: 2 | K17: X | L17: =A44 -> 43
A18: 17 | B18: 17 | C18: Mampu merancang, merakit, dan memprogram sistem kontrol otomasi industri berbasis PLC, SCADA, serta pneumatik/hidrolik. Selain itu, terampil dalam melakukan troubleshooting dan mengoperasikan sistem robotika industri sesuai dengan standar K3. | D18: 2025/2026 | E18: 6 | F18: =A18 -> 17 | H18: =B45 -> 10 | I18: =VLOOKUP(B45,'2'!$A$2:$B$39,2,FALSE) -> Dasar-dasar Teknik Sepeda Motor | J18: 2 | K18: X | L18: =A45 -> 44
A19: 18 | B19: 18 | C19: Anda memiliki keahlian dalam perancangan arsitektur jaringan skala besar, mulai dari pengaturan routing dinamis hingga optimasi bandwidth. Selain itu, Anda terampil dalam aspek keamanan jaringan nirkabel serta konfigurasi layanan server dan cloud, yang merupakan fondasi krusial dalam infrastruktur TI modern. | D19: 2025/2026 | E19: 6 | F19: =A19 -> 18 | H19: =B46 -> 8 | I19: =VLOOKUP(B46,'2'!$A$2:$B$39,2,FALSE) -> Dasar-dasar Teknik Otomasi Industri | J19: 2 | K19: X | L19: =A46 -> 45
A20: 19 | B20: 19 | C20: Ahli diagnosis & perbaikan mesin (overhaul), kalibrasi injeksi PGM-FI/FI, serta perbaikan kelistrikan bodi & sasis motor sesuai SOP. | D20: 2025/2026 | E20: 6 | F20: =A20 -> 19 | H20: =B47 -> 11 | I20: =VLOOKUP(B47,'2'!$A$2:$B$39,2,FALSE) -> Muatan Lokal Bahasa Daerah | J20: 2 | K20: X | L20: =A47 -> 46
A21: 20 | B21: 20 | C21: Mampu merancang arsitektur sistem IoT, mengintegrasikan sensor dan aktuator dengan mikrokontroler, membangun komunikasi data via protokol MQTT/HTTP, serta menampilkan data real-time di dashboard atau cloud platform. | D21: 2025/2026 | E21: 6 | F21: =A21 -> 20 | H21: =B48 -> 24 | I21: Kursus Bahasa Korea | J21: 2 | K21: X | L21: =A48 -> 47
A22: 21 | B22: 21 | C22: Mampu merancang diagram skematik dan layout mekanikal, instalasi listrik (PUIL), panel otomasi, serta sistem perpipaan menggunakan perangkat lunak CAD sesuai standar teknik internasional. | D22: 2025/2026 | E22: 6 | F22: =A22 -> 21 | H22: 24A | I22: Kursus Bahasa Jepang | J22: 2 | K22: X | L22: =A49 -> 48
A23: 22 | B23: 22 | C23: Mampu menganalisis gambar kerja manufaktur kompleks, menyusun urutan proses (process planning), menulis kode CNC (G-code/M-code) secara manual maupun berbasis CAM, serta melakukan simulasi pergerakan pahat dengan aman. | D23: 2025/2026 | E23: 6 | F23: =A23 -> 22 | H23: =B50 -> 25 | I23: =VLOOKUP(B50,'2'!$A$2:$B$39,2,FALSE) -> Pramuka | J23: 3 | K23: X | L23: =A50 -> 49
A24: 23 | B24: 23 | C24: Mampu membaca, menganalisis, dan membuat gambar teknik 2D maupun model 3D untuk sasis dan modifikasi motor, lengkap dengan penerapan anotasi, proyeksi, serta toleransi linier dan geometris secara presisi. | D24: 2025/2026 | E24: 6 | F24: =A24 -> 23
A25: 24 | B25: 24 | C25: Peserta didik dapat mengikuti kursus Bahasa Jepang dengan sangat baik | D25: 2025/2026 | E25: 6 | F25: =A25 -> 24
A26: 25 | B26: 24 | C26: Peserta Didik Mampu Mengikuti Kursus Bahasa Korea dengan Sangat Baik | D26: 2025/2026 | E26: 6 | F26: =A26 -> 25
A27: 26 | B27: 24 | C27: Peserta didik dapat mengikuti kursus Bahasa Jepang dengan baik | D27: 2025/2026 | E27: 6 | F27: =A27 -> 26 | H27: =B51 -> 1 | I27: =VLOOKUP(B51,'2'!$A$2:$B$39,2,FALSE) -> Pendidikan Agama Islam dan Budi Pekerti | J27: 4 | K27: XI | L27: =A51 -> 50
A28: 27 | B28: 24 | C28: Peserta Didik Mampu Mengikuti Kursus Bahasa Korea dengan Baik | D28: 2025/2026 | E28: 6 | F28: =A28 -> 27 | H28: =B52 -> 2 | I28: =VLOOKUP(B52,'2'!$A$2:$B$39,2,FALSE) -> Pendidikan Agama Hindu dan Budi Pekerti | J28: 4 | K28: XI | L28: =A52 -> 51
A29: 28 | B29: 1 | C29: Mampu menganalisis ayat Al-Qur'an tentang syu'abul iman dan menerapkannya dalam akhlak mulia sehari-hari. | D29: 2025/2026 | E29: 2 | F29: =A29 -> 28 | H29: =B53 -> 3 | I29: =VLOOKUP(B53,'2'!$A$2:$B$39,2,FALSE) -> Pendidikan Agama Kristen dan Budi Pekerti | J29: 4 | K29: XI | L29: =A53 -> 52
A30: 29 | B30: 2 | C30: Mampu menganalisis nilai yajna dalam kitab Ramayana serta kontribusi sejarah Hindu di Asia bagi kehidupan. | D30: 2025/2026 | E30: 2 | F30: =A30 -> 29 | H30: =B54 -> 33 | I30: =VLOOKUP(B54,'2'!$A$2:$B$39,2,FALSE) -> Pendidikan Agama Katholik dan Budi Pekerti | J30: 4 | K30: XI | L30: =A54 -> 53
A31: 30 | B31: 3 | C31: Mampu memahami hidup baru dalam Kristus dengan mengembangkan sikap adil dan bela rasa terhadap sesama. | D31: 2025/2026 | E31: 2 | F31: =A31 -> 30 | H31: =B55 -> 4 | I31: =VLOOKUP(B55,'2'!$A$2:$B$39,2,FALSE) -> Pendidikan Pancasila | J31: 4 | K31: XI | L31: =A55 -> 54
A32: 31 | B32: 33 | C32: Mampu meneladan Yesus Kristus sebagai idola dan sahabat sejati dalam mewujudkan iman di masyarakat. | D32: 2025/2026 | E32: 2 | F32: =A32 -> 31 | H32: =B56 -> 26 | I32: =VLOOKUP(B56,'2'!$A$2:$B$39,2,FALSE) -> Pendidikan Jasmani, Olahraga, dan Kesehatan | J32: 4 | K32: XI | L32: =A56 -> 55
A33: 32 | B33: 4 | C33: Mampu menganalisis peluang tantangan penerapan Pancasila dan menginisiasi kegiatan gotong royong. | D33: 2025/2026 | E33: 2 | F33: =A33 -> 32 | H33: =B57 -> 5 | I33: =VLOOKUP(B57,'2'!$A$2:$B$39,2,FALSE) -> Sejarah | J33: 4 | K33: XI | L33: =A57 -> 56
A34: 33 | B34: 12 | C34: Mampu mengevaluasi gagasan teks biografi, melakukan negosiasi bisnis, dan menulis teks diskusi dengan logis. | D34: 2025/2026 | E34: 2 | F34: =A34 -> 33 | H34: =B58 -> 13 | I34: =VLOOKUP(B58,'2'!$A$2:$B$39,2,FALSE) -> Matematika (Umum) | J34: 4 | K34: XI | L34: =A58 -> 57
A35: 34 | B35: 26 | C35: Mampu mempraktikkan keterampilan gerak spesifik olahraga permainan dan menganalisis konsep kebugaran jasmani. | D35: 2025/2026 | E35: 2 | F35: =A35 -> 34 | H35: =B59 -> 14 | I35: =VLOOKUP(B59,'2'!$A$2:$B$39,2,FALSE) -> Bahasa Inggris | J35: 4 | K35: XI | L35: =A59 -> 58
A36: 35 | B36: 5 | C36: Mampu menganalisis keterkaitan peristiwa sejarah lokal dengan sejarah nasional secara kronologis. | D36: 2025/2026 | E36: 2 | F36: =A36 -> 35 | H36: =B60 -> 18 | I36: =VLOOKUP(B60,'2'!$A$2:$B$39,2,FALSE) -> Konsentrasi Keahlian Teknik Komputer dan Jaringan | J36: 4 | K36: XI | L36: =A60 -> 59
A37: 36 | B37: 6 | C37: Mampu mengapresiasi keunikan ragam hias daerah dan mengkreasi karya seni rupa/pertunjukan secara kreatif. | D37: 2025/2026 | E37: 2 | F37: =A37 -> 36 | H37: =B61 -> 30 | I37: =VLOOKUP(B61,'2'!$A$2:$B$39,2,FALSE) -> Projek Kreatif dan Kewirausahaan | J37: 4 | K37: XI | L37: =A61 -> 60
A38: 37 | B38: 27 | C38: Mampu merancang logika pemrograman dasar phyton dan memahami konsep dasar pemanfaatan teknologi AI. | D38: 2025/2026 | E38: 2 | F38: =A38 -> 37 | H38: =B62 -> 20 | I38: =VLOOKUP(B62,'2'!$A$2:$B$39,2,FALSE) -> Sistem Perancangan IoT | J38: 4 | K38: XI | L38: =A62 -> 61
... A47: 46 | B47: 11 | C47: Mampu menganalisis sengkalan/crita rakyat dan mempraktikkan unggah-ungguh basa dalam teks pacelathon. | D47: 2025/2026 | E47: 2 | F47: =A47 -> 46 | H47: =B71 -> 24 | I47: =VLOOKUP(B71,'2'!$A$2:$B$39,2,FALSE) -> Kursus Bahasa Asing | J47: 4 | K47: XI | L47: =A71 -> 70
A48: 47 | B48: 24 | C48: Mengikuti Kursus Bahasa Korea | D48: 2025/2026 | E48: 2 | F48: =A48 -> 47 | H48: =B72 -> 0 | L48: =A72 -> 0
...

Sheet 4
A1: level | B1: class | C1: kelas | D1: id | E1: teacher_registration_number | F1: teacher_name | G1: teacher_title | J1: 13 | K1: 10
D2: 1 | E2: 10 | F2: Tri Haryoko | G2: S.Pd.
D3: 2 | E3: 20 | F3: Reni Loly Mardianawati | G3: S.Pd.
D4: 3 | E4: 30 | F4: Rita Indahwati | G4: S.Pd.
D5: 4 | E5: 40 | F5: Angkit Sabekti | G5: S.T.
D6: 5 | E6: 50 | F6: Dra. Nur Hidayati | G6: S.Pd.
D7: 6 | E7: 60 | F7: Supandari | G7: S.Pd.
D8: 7 | E8: 70 | F8: Aji Widi | G8: S.Pd.
D9: 8 | E9: 80 | F9: Faaruq Umar Ibnu Chatab Al Amin | G9: S.Pd.
D10: 9 | E10: 90 | F10: Lutfi Arina | G10: S.Pd.
A11: X | B11: TJKT 1 | C11: =_xlfn.CONCAT(A11," ",B11) -> X TJKT 1 | D11: 10 | E11: 100 | F11: Aun Gentara Firdausya Gusty | G11: S.Pd.
A12: XI | B12: TJKT 1 | C12: =_xlfn.CONCAT(A12," ",B12) -> XI TJKT 1 | D12: 11 | E12: 110 | F12: Irfandi Tri Pamungkas | G12: S.Pd. | J12: X | K12: =COUNTIF($A$11:$A$40,"=X") -> 13
A13: X | B13: TJKT 2 | C13: =_xlfn.CONCAT(A13," ",B13) -> X TJKT 2 | D13: 12 | E13: 120 | F13: Dian Puspitasari | G13: S.Sn. | J13: XI | K13: =COUNTIF($A$11:$A$40,"=XI") -> 10
A14: XI | B14: TJKT 2 | C14: =_xlfn.CONCAT(A14," ",B14) -> XI TJKT 2 | D14: 13 | E14: 130 | F14: Fitriyanda Bagus Saputra | G14: S.Pd. | K14: =SUM(K12:K13) -> 23
A15: X | B15: TOI 1 | C15: =_xlfn.CONCAT(A15," ",B15) -> X TOI 1 | D15: 14 | E15: 140 | F15: Anastasia Anik Pujianti | G15: S.Pd.
A16: XI | B16: TOI 1 | C16: =_xlfn.CONCAT(A16," ",B16) -> XI TOI 1 | D16: 15 | E16: 150 | F16: Vitria Indriyani Setyaningsih | G16: S.Kom, M.Pd
A17: X | B17: TOI 2 | C17: =_xlfn.CONCAT(A17," ",B17) -> X TOI 2 | D17: 16 | E17: 160 | F17: Isnaini Nurhidayah | G17: S.Pd.
A18: XI | B18: TOI 2 | C18: =_xlfn.CONCAT(A18," ",B18) -> XI TOI 2 | D18: 17 | E18: 170 | F18: Tiara Surya Madani | G18: S.Pd.
A19: X | B19: TOI 3 | C19: =_xlfn.CONCAT(A19," ",B19) -> X TOI 3 | D19: 18 | E19: 180 | F19: Adha Nur Qahar | G19: S.T.
A20: X | B20: TP 1 | C20: =_xlfn.CONCAT(A20," ",B20) -> X TP 1 | D20: 19 | E20: 190 | F20: Okky Uung Wijaya | G20: S.Pd.
A21: XI | B21: TP 1 | C21: =_xlfn.CONCAT(A21," ",B21) -> XI TP 1 | D21: 20 | E21: 200 | F21: Tantri Purwanti | G21: S.Pd.
A22: X | B22: TP 2 | C22: =_xlfn.CONCAT(A22," ",B22) -> X TP 2 | D22: 21 | E22: 210 | F22: Heri Setyawan | G22: S.Pd.
A23: XI | B23: TP 2 | C23: =_xlfn.CONCAT(A23," ",B23) -> XI TP 2 | D23: 22 | E23: 220 | F23: Yesi Setyorini | G23: S.Pd.
A24: XI | B24: TP 3 | C24: =_xlfn.CONCAT(A24," ",B24) -> XI TP 3 | D24: 23 | E24: 230 | F24: Sri Wahyuni | G24: S.Pd.
A25: X | B25: TP 3 | C25: =_xlfn.CONCAT(A25," ",B25) -> X TP 3 | D25: 24 | E25: 240 | F25: Sri Adiningsih Utami N | G25: M.Pd.
A26: X | B26: TP 4 | C26: =_xlfn.CONCAT(A26," ",B26) -> X TP 4 | D26: 25 | E26: 250 | F26: Yuni Dwi Hastutik | G26: S.Pd.
... A33: X | B33: TSM 3 | C33: =_xlfn.CONCAT(A33," ",B33) -> X TSM 3 | D33: 32 | E33: 320 | F33: Muhid Murtadho | G33: S.Pd.
D34: 33 | E34: 330 | F34: Kiryanto | G34: S.Pd.
D35: 34 | E35: 340 | F35: Budi Jarwanto | G35: S.Pd.
D36: 35 | E36: 350 | F36: Istanto | G36: S.Kom, M.Pd
D37: 36 | E37: 360 | F37: Fadila Fauzia Firdaus | G37: S.Pd.
D38: 37 | E38: 370 | F38: Yusuf Adi Khurniawan | G38: S.T.
D39: 38 | E39: 380 | F39: Ady Prasetyo | G39: S.T.
D40: 39 | E40: 390 | F40: Haris Willyanto | G40: S.T.
C65: =_xlfn.CONCAT(A65," ",B65) | E65: 330
C66: =_xlfn.CONCAT(A66," ",B66) | E66: 340
C67: =_xlfn.CONCAT(A67," ",B67) | E67: 350
C68: =_xlfn.CONCAT(A68," ",B68) | E68: 360
C69: =_xlfn.CONCAT(A69," ",B69) | E69: 370
C70: =_xlfn.CONCAT(A70," ",B70) | E70: 380
...

Sheet 5
A1: kelas | B1: 12 | M1: kelas | N1: 10 | V1: Sakit | W1: Ijin | X1: Alpa | AB1: kelas | AC1: 11 | AK1: Sakit | AL1: Ijin | AM1: Alpa
A2: history id | B2: nis | C2: nisn | D2: name | F2: Ijin | G2: Sakit | H2: Alpa | M2: history id | N2: nis | O2: nisn | P2: name | Q2: id class | R2: wali kelas | S2: kelas | T2: level | U2: class | AB2: nis | AC2: nisn | AD2: name | AE2: history id | AF2: id class | AG2: wali kelas | AH2: kelas | AI2: level | AJ2: class
A3: 1 | B3: 13491 | C3: '0076766535 | D3: Afria Andri Imam Solikhin | E3: XII TKJ 1 | G3: 0 | H3: 3 | I3: TKJ 1 | J3: 1 | M3: 264 | N3: 14162 | P3: Aisha Nurfadhila | Q3: =VLOOKUP(S3,'6'!$I$2:$J$33,2,FALSE) -> 10 | R3: =VLOOKUP(S3,'4'!$C$11:$F$33,2,FALSE) -> 10 | S3: =_xlfn.CONCAT(T3," ",U3) -> X TJKT 1 | T3: X | U3: TJKT 1 | V3: =VLOOKUP(P3,[1]Sheet1!$B$2:$E$393,2,FALSE) -> 0 | W3: =VLOOKUP(P3,[1]Sheet1!$B$2:$E$393,3,FALSE) -> 0 | X3: =VLOOKUP(P3,[1]Sheet1!$B$2:$E$393,4,FALSE) -> 0 | AB3: 13803 | AD3: Abdul Rohmat Yulianto | AE3: 630 | AF3: =VLOOKUP(AH3,'6'!$I$2:$J$33,2,FALSE) -> 23 | AG3: =VLOOKUP(AH3,'4'!$C$11:$F$33,2,FALSE) -> 11 | AH3: =_xlfn.CONCAT(AI3," ",AJ3) -> XI TJKT 1 | AI3: XI | AJ3: TJKT 1 | AK3: =VLOOKUP(AD3,[1]xi!$B$3:$E$208,2,FALSE) -> #N/A | AL3: =VLOOKUP(AD3,[1]xi!$B$3:$E$208,3,FALSE) -> #N/A | AM3: =VLOOKUP(AD3,[1]xi!$B$3:$E$208,4,FALSE) -> #N/A | AN3: PKL
A4: 2 | B4: 13493 | C4: '0085280042 | D4: Ahmad Rizky Mubaroq | E4: XII TKJ 1 | F4: 0 | G4: 0 | H4: 0 | I4: TKJ 1 | J4: 1 | M4: 265 | N4: 14163 | P4: Alvino Maulana Rasya | Q4: =VLOOKUP(S4,'6'!$I$2:$J$33,2,FALSE) -> 10 | R4: =VLOOKUP(S4,'4'!$C$11:$F$33,2,FALSE) -> 10 | S4: =_xlfn.CONCAT(T4," ",U4) -> X TJKT 1 | T4: X | U4: TJKT 1 | V4: =VLOOKUP(P4,[1]Sheet1!$B$2:$E$393,2,FALSE) -> 0 | W4: =VLOOKUP(P4,[1]Sheet1!$B$2:$E$393,3,FALSE) -> 0 | X4: =VLOOKUP(P4,[1]Sheet1!$B$2:$E$393,4,FALSE) -> 0 | AB4: 13804 | AD4: Abi Becam Syah | AE4: 631 | AF4: =VLOOKUP(AH4,'6'!$I$2:$J$33,2,FALSE) -> 23 | AG4: =VLOOKUP(AH4,'4'!$C$11:$F$33,2,FALSE) -> 11 | AH4: =_xlfn.CONCAT(AI4," ",AJ4) -> XI TJKT 1 | AI4: XI | AJ4: TJKT 1 | AK4: =VLOOKUP(AD4,[1]xi!$B$3:$E$208,2,FALSE) -> #N/A | AL4: =VLOOKUP(AD4,[1]xi!$B$3:$E$208,3,FALSE) -> #N/A | AM4: =VLOOKUP(AD4,[1]xi!$B$3:$E$208,4,FALSE) -> #N/A | AN4: PKL
A5: 3 | B5: 13494 | C5: '0088221596 | D5: Alvaro Christian Widhiatama | E5: XII TKJ 1 | F5: 0 | G5: 0 | H5: 0 | I5: TKJ 1 | J5: 1 | M5: 266 | N5: 14164 | P5: Alvis Bramantya Putra | Q5: =VLOOKUP(S5,'6'!$I$2:$J$33,2,FALSE) -> 10 | R5: =VLOOKUP(S5,'4'!$C$11:$F$33,2,FALSE) -> 10 | S5: =_xlfn.CONCAT(T5," ",U5) -> X TJKT 1 | T5: X | U5: TJKT 1 | V5: =VLOOKUP(P5,[1]Sheet1!$B$2:$E$393,2,FALSE) -> 0 | W5: =VLOOKUP(P5,[1]Sheet1!$B$2:$E$393,3,FALSE) -> 0 | X5: =VLOOKUP(P5,[1]Sheet1!$B$2:$E$393,4,FALSE) -> 0 | AB5: 13805 | AD5: Abi Manyu | AE5: 632 | AF5: =VLOOKUP(AH5,'6'!$I$2:$J$33,2,FALSE) -> 23 | AG5: =VLOOKUP(AH5,'4'!$C$11:$F$33,2,FALSE) -> 11 | AH5: =_xlfn.CONCAT(AI5," ",AJ5) -> XI TJKT 1 | AI5: XI | AJ5: TJKT 1 | AK5: =VLOOKUP(AD5,[1]xi!$B$3:$E$208,2,FALSE) -> #N/A | AL5: =VLOOKUP(AD5,[1]xi!$B$3:$E$208,3,FALSE) -> #N/A | AM5: =VLOOKUP(AD5,[1]xi!$B$3:$E$208,4,FALSE) -> #N/A | AN5: PKL
A6: 4 | B6: 13495 | C6: '0084691033 | D6: Amelia Permata Titian | E6: XII TKJ 1 | F6: 0 | G6: 0 | H6: 3 | I6: TKJ 1 | J6: 1 | M6: 267 | N6: 14165 | P6: Anggita Sabekti | Q6: =VLOOKUP(S6,'6'!$I$2:$J$33,2,FALSE) -> 10 | R6: =VLOOKUP(S6,'4'!$C$11:$F$33,2,FALSE) -> 10 | S6: =_xlfn.CONCAT(T6," ",U6) -> X TJKT 1 | T6: X | U6: TJKT 1 | V6: =VLOOKUP(P6,[1]Sheet1!$B$2:$E$393,2,FALSE) -> 0 | W6: =VLOOKUP(P6,[1]Sheet1!$B$2:$E$393,3,FALSE) -> 0 | X6: =VLOOKUP(P6,[1]Sheet1!$B$2:$E$393,4,FALSE) -> 0 | AB6: 13806 | AD6: Affan Fahrozi | AE6: 633 | AF6: =VLOOKUP(AH6,'6'!$I$2:$J$33,2,FALSE) -> 23 | AG6: =VLOOKUP(AH6,'4'!$C$11:$F$33,2,FALSE) -> 11 | AH6: =_xlfn.CONCAT(AI6," ",AJ6) -> XI TJKT 1 | AI6: XI | AJ6: TJKT 1 | AK6: =VLOOKUP(AD6,[1]xi!$B$3:$E$208,2,FALSE) -> #N/A | AL6: =VLOOKUP(AD6,[1]xi!$B$3:$E$208,3,FALSE) -> #N/A | AM6: =VLOOKUP(AD6,[1]xi!$B$3:$E$208,4,FALSE) -> #N/A | AN6: PKL
A7: 5 | B7: 13496 | C7: '0086206662 | D7: Andhika Danu Perdana | E7: XII TKJ 1 | F7: 0 | G7: 0 | H7: 0 | I7: TKJ 1 | J7: 1 | M7: 268 | N7: 14166 | P7: Arvina Novellyana | Q7: =VLOOKUP(S7,'6'!$I$2:$J$33,2,FALSE) -> 10 | R7: =VLOOKUP(S7,'4'!$C$11:$F$33,2,FALSE) -> 10 | S7: =_xlfn.CONCAT(T7," ",U7) -> X TJKT 1 | T7: X | U7: TJKT 1 | V7: =VLOOKUP(P7,[1]Sheet1!$B$2:$E$393,2,FALSE) -> 0 | W7: =VLOOKUP(P7,[1]Sheet1!$B$2:$E$393,3,FALSE) -> 0 | X7: =VLOOKUP(P7,[1]Sheet1!$B$2:$E$393,4,FALSE) -> 0 | AB7: 13807 | AD7: Ajeng Viera Putri Ramadhani | AE7: 634 | AF7: =VLOOKUP(AH7,'6'!$I$2:$J$33,2,FALSE) -> 23 | AG7: =VLOOKUP(AH7,'4'!$C$11:$F$33,2,FALSE) -> 11 | AH7: =_xlfn.CONCAT(AI7," ",AJ7) -> XI TJKT 1 | AI7: XI | AJ7: TJKT 1 | AK7: =VLOOKUP(AD7,[1]xi!$B$3:$E$208,2,FALSE) -> #N/A | AL7: =VLOOKUP(AD7,[1]xi!$B$3:$E$208,3,FALSE) -> #N/A | AM7: =VLOOKUP(AD7,[1]xi!$B$3:$E$208,4,FALSE) -> #N/A | AN7: PKL
A8: 6 | B8: 13497 | C8: '0082636617 | D8: Bella Aprilia | E8: XII TKJ 1 | F8: 0 | G8: 1 | H8: 2 | I8: TKJ 1 | J8: 1 | M8: 269 | N8: 14167 | P8: Asyifa Fatimah Azzahra | Q8: =VLOOKUP(S8,'6'!$I$2:$J$33,2,FALSE) -> 10 | R8: =VLOOKUP(S8,'4'!$C$11:$F$33,2,FALSE) -> 10 | S8: =_xlfn.CONCAT(T8," ",U8) -> X TJKT 1 | T8: X | U8: TJKT 1 | V8: =VLOOKUP(P8,[1]Sheet1!$B$2:$E$393,2,FALSE) -> 0 | W8: =VLOOKUP(P8,[1]Sheet1!$B$2:$E$393,3,FALSE) -> 0 | X8: =VLOOKUP(P8,[1]Sheet1!$B$2:$E$393,4,FALSE) -> 0 | AB8: 13808 | AD8: Aldo Muhammad Kurniawan | AE8: 635 | AF8: =VLOOKUP(AH8,'6'!$I$2:$J$33,2,FALSE) -> 23 | AG8: =VLOOKUP(AH8,'4'!$C$11:$F$33,2,FALSE) -> 11 | AH8: =_xlfn.CONCAT(AI8," ",AJ8) -> XI TJKT 1 | AI8: XI | AJ8: TJKT 1 | AK8: =VLOOKUP(AD8,[1]xi!$B$3:$E$208,2,FALSE) -> #N/A | AL8: =VLOOKUP(AD8,[1]xi!$B$3:$E$208,3,FALSE) -> #N/A | AM8: =VLOOKUP(AD8,[1]xi!$B$3:$E$208,4,FALSE) -> #N/A | AN8: PKL
A9: 7 | B9: 13498 | C9: '0089202248 | D9: Chandra Deny Prasetyo | E9: XII TKJ 1 | F9: 0 | G9: 0 | H9: 3 | I9: TKJ 1 | J9: 1 | M9: 270 | N9: 14168 | P9: Bagas Saputra Pratama | Q9: =VLOOKUP(S9,'6'!$I$2:$J$33,2,FALSE) -> 10 | R9: =VLOOKUP(S9,'4'!$C$11:$F$33,2,FALSE) -> 10 | S9: =_xlfn.CONCAT(T9," ",U9) -> X TJKT 1 | T9: X | U9: TJKT 1 | V9: =VLOOKUP(P9,[1]Sheet1!$B$2:$E$393,2,FALSE) -> 0 | W9: =VLOOKUP(P9,[1]Sheet1!$B$2:$E$393,3,FALSE) -> 0 | X9: =VLOOKUP(P9,[1]Sheet1!$B$2:$E$393,4,FALSE) -> 1 | AB9: 13809 | AD9: Alfian Hafizh Arkhan | AE9: 636 | AF9: =VLOOKUP(AH9,'6'!$I$2:$J$33,2,FALSE) -> 23 | AG9: =VLOOKUP(AH9,'4'!$C$11:$F$33,2,FALSE) -> 11 | AH9: =_xlfn.CONCAT(AI9," ",AJ9) -> XI TJKT 1 | AI9: XI | AJ9: TJKT 1 | AK9: =VLOOKUP(AD9,[1]xi!$B$3:$E$208,2,FALSE) -> #N/A | AL9: =VLOOKUP(AD9,[1]xi!$B$3:$E$208,3,FALSE) -> #N/A | AM9: =VLOOKUP(AD9,[1]xi!$B$3:$E$208,4,FALSE) -> #N/A | AN9: PKL
A10: 8 | B10: 13499 | C10: '0087295364 | D10: Dava Alifian Putra | E10: XII TKJ 1 | F10: 0 | G10: 0 | H10: 0 | I10: TKJ 1 | J10: 1 | M10: 271 | N10: 14169 | P10: Desi Natasya | Q10: =VLOOKUP(S10,'6'!$I$2:$J$33,2,FALSE) -> 10 | R10: =VLOOKUP(S10,'4'!$C$11:$F$33,2,FALSE) -> 10 | S10: =_xlfn.CONCAT(T10," ",U10) -> X TJKT 1 | T10: X | U10: TJKT 1 | V10: =VLOOKUP(P10,[1]Sheet1!$B$2:$E$393,2,FALSE) -> 0 | W10: =VLOOKUP(P10,[1]Sheet1!$B$2:$E$393,3,FALSE) -> 0 | X10: =VLOOKUP(P10,[1]Sheet1!$B$2:$E$393,4,FALSE) -> 0 | AB10: 13810 | AD10: Arief Rahmat Sholeh | AE10: 637 | AF10: =VLOOKUP(AH10,'6'!$I$2:$J$33,2,FALSE) -> 23 | AG10: =VLOOKUP(AH10,'4'!$C$11:$F$33,2,FALSE) -> 11 | AH10: =_xlfn.CONCAT(AI10," ",AJ10) -> XI TJKT 1 | AI10: XI | AJ10: TJKT 1 | AK10: =VLOOKUP(AD10,[1]xi!$B$3:$E$208,2,FALSE) -> #N/A | AL10: =VLOOKUP(AD10,[1]xi!$B$3:$E$208,3,FALSE) -> #N/A | AM10: =VLOOKUP(AD10,[1]xi!$B$3:$E$208,4,FALSE) -> #N/A | AN10: PKL
A11: 9 | B11: 13500 | C11: '0074432651 | D11: Eka Putri Ramadhani | E11: XII TKJ 1 | F11: 0 | G11: 0 | H11: 2 | I11: TKJ 1 | J11: 1 | M11: 272 | N11: 14170 | P11: Desi Puteri Arsiska | Q11: =VLOOKUP(S11,'6'!$I$2:$J$33,2,FALSE) -> 10 | R11: =VLOOKUP(S11,'4'!$C$11:$F$33,2,FALSE) -> 10 | S11: =_xlfn.CONCAT(T11," ",U11) -> X TJKT 1 | T11: X | U11: TJKT 1 | V11: =VLOOKUP(P11,[1]Sheet1!$B$2:$E$393,2,FALSE) -> 0 | W11: =VLOOKUP(P11,[1]Sheet1!$B$2:$E$393,3,FALSE) -> 0 | X11: =VLOOKUP(P11,[1]Sheet1!$B$2:$E$393,4,FALSE) -> 0 | AB11: 13811 | AD11: Aris Firmansyah | AE11: 638 | AF11: =VLOOKUP(AH11,'6'!$I$2:$J$33,2,FALSE) -> 23 | AG11: =VLOOKUP(AH11,'4'!$C$11:$F$33,2,FALSE) -> 11 | AH11: =_xlfn.CONCAT(AI11," ",AJ11) -> XI TJKT 1 | AI11: XI | AJ11: TJKT 1 | AK11: =VLOOKUP(AD11,[1]xi!$B$3:$E$208,2,FALSE) -> #N/A | AL11: =VLOOKUP(AD11,[1]xi!$B$3:$E$208,3,FALSE) -> #N/A | AM11: =VLOOKUP(AD11,[1]xi!$B$3:$E$208,4,FALSE) -> #N/A | AN11: PKL
A12: 10 | B12: 13501 | C12: '0086051128 | D12: Elina Trihapsari | E12: XII TKJ 1 | F12: 1 | G12: 0 | H12: 2 | I12: TKJ 1 | J12: 1 | M12: 273 | N12: 14171 | P12: Destina Kasih | Q12: =VLOOKUP(S12,'6'!$I$2:$J$33,2,FALSE) -> 10 | R12: =VLOOKUP(S12,'4'!$C$11:$F$33,2,FALSE) -> 10 | S12: =_xlfn.CONCAT(T12," ",U12) -> X TJKT 1 | T12: X | U12: TJKT 1 | V12: =VLOOKUP(P12,[1]Sheet1!$B$2:$E$393,2,FALSE) -> 1 | W12: =VLOOKUP(P12,[1]Sheet1!$B$2:$E$393,3,FALSE) -> 0 | X12: =VLOOKUP(P12,[1]Sheet1!$B$2:$E$393,4,FALSE) -> 1 | AB12: 13812 | AD12: Ashe Ardhana Putra | AE12: 639 | AF12: =VLOOKUP(AH12,'6'!$I$2:$J$33,2,FALSE) -> 23 | AG12: =VLOOKUP(AH12,'4'!$C$11:$F$33,2,FALSE) -> 11 | AH12: =_xlfn.CONCAT(AI12," ",AJ12) -> XI TJKT 1 | AI12: XI | AJ12: TJKT 1 | AK12: =VLOOKUP(AD12,[1]xi!$B$3:$E$208,2,FALSE) -> #N/A | AL12: =VLOOKUP(AD12,[1]xi!$B$3:$E$208,3,FALSE) -> #N/A | AM12: =VLOOKUP(AD12,[1]xi!$B$3:$E$208,4,FALSE) -> #N/A | AN12: PKL
A13: 11 | B13: 13502 | C13: '3086633600 | D13: Evan Seva Arahman | E13: XII TKJ 1 | F13: 0 | G13: 0 | H13: 1 | I13: TKJ 1 | J13: 1 | M13: 274 | N13: 14172 | P13: Dio Ivan Kurnia | Q13: =VLOOKUP(S13,'6'!$I$2:$J$33,2,FALSE) -> 10 | R13: =VLOOKUP(S13,'4'!$C$11:$F$33,2,FALSE) -> 10 | S13: =_xlfn.CONCAT(T13," ",U13) -> X TJKT 1 | T13: X | U13: TJKT 1 | V13: =VLOOKUP(P13,[1]Sheet1!$B$2:$E$393,2,FALSE) -> 1 | W13: =VLOOKUP(P13,[1]Sheet1!$B$2:$E$393,3,FALSE) -> 0 | X13: =VLOOKUP(P13,[1]Sheet1!$B$2:$E$393,4,FALSE) -> 1 | AB13: 13813 | AD13: Asiska Pangesti | AE13: 640 | AF13: =VLOOKUP(AH13,'6'!$I$2:$J$33,2,FALSE) -> 23 | AG13: =VLOOKUP(AH13,'4'!$C$11:$F$33,2,FALSE) -> 11 | AH13: =_xlfn.CONCAT(AI13," ",AJ13) -> XI TJKT 1 | AI13: XI | AJ13: TJKT 1 | AK13: =VLOOKUP(AD13,[1]xi!$B$3:$E$208,2,FALSE) -> #N/A | AL13: =VLOOKUP(AD13,[1]xi!$B$3:$E$208,3,FALSE) -> #N/A | AM13: =VLOOKUP(AD13,[1]xi!$B$3:$E$208,4,FALSE) -> #N/A | AN13: PKL
A14: 12 | B14: 13503 | C14: '0089443556 | D14: Ghani Ikhwan Fauzi | E14: XII TKJ 1 | F14: 0 | G14: 0 | H14: 1 | I14: TKJ 1 | J14: 1 | M14: 275 | N14: 14173 | P14: Febriana Alya Zarifa | Q14: =VLOOKUP(S14,'6'!$I$2:$J$33,2,FALSE) -> 10 | R14: =VLOOKUP(S14,'4'!$C$11:$F$33,2,FALSE) -> 10 | S14: =_xlfn.CONCAT(T14," ",U14) -> X TJKT 1 | T14: X | U14: TJKT 1 | V14: =VLOOKUP(P14,[1]Sheet1!$B$2:$E$393,2,FALSE) -> 0 | W14: =VLOOKUP(P14,[1]Sheet1!$B$2:$E$393,3,FALSE) -> 0 | X14: =VLOOKUP(P14,[1]Sheet1!$B$2:$E$393,4,FALSE) -> 1 | AB14: 13814 | AD14: Asokawati Ning Kusuma | AE14: 641 | AF14: =VLOOKUP(AH14,'6'!$I$2:$J$33,2,FALSE) -> 23 | AG14: =VLOOKUP(AH14,'4'!$C$11:$F$33,2,FALSE) -> 11 | AH14: =_xlfn.CONCAT(AI14," ",AJ14) -> XI TJKT 1 | AI14: XI | AJ14: TJKT 1 | AK14: =VLOOKUP(AD14,[1]xi!$B$3:$E$208,2,FALSE) -> #N/A | AL14: =VLOOKUP(AD14,[1]xi!$B$3:$E$208,3,FALSE) -> #N/A | AM14: =VLOOKUP(AD14,[1]xi!$B$3:$E$208,4,FALSE) -> #N/A | AN14: PKL
A15: 13 | B15: 13505 | C15: '0078321428 | D15: Keysa Citra Lestari | E15: XII TKJ 1 | F15: 0 | G15: 1 | H15: 2 | I15: TKJ 1 | J15: 1 | M15: 276 | N15: 14174 | P15: Figo Eka Prasetyo | Q15: =VLOOKUP(S15,'6'!$I$2:$J$33,2,FALSE) -> 10 | R15: =VLOOKUP(S15,'4'!$C$11:$F$33,2,FALSE) -> 10 | S15: =_xlfn.CONCAT(T15," ",U15) -> X TJKT 1 | T15: X | U15: TJKT 1 | V15: =VLOOKUP(P15,[1]Sheet1!$B$2:$E$393,2,FALSE) -> 0 | W15: =VLOOKUP(P15,[1]Sheet1!$B$2:$E$393,3,FALSE) -> 0 | X15: =VLOOKUP(P15,[1]Sheet1!$B$2:$E$393,4,FALSE) -> 1 | AB15: 13815 | AD15: Budi Utomo | AE15: 642 | AF15: =VLOOKUP(AH15,'6'!$I$2:$J$33,2,FALSE) -> 23 | AG15: =VLOOKUP(AH15,'4'!$C$11:$F$33,2,FALSE) -> 11 | AH15: =_xlfn.CONCAT(AI15," ",AJ15) -> XI TJKT 1 | AI15: XI | AJ15: TJKT 1 | AK15: =VLOOKUP(AD15,[1]xi!$B$3:$E$208,2,FALSE) -> #N/A | AL15: =VLOOKUP(AD15,[1]xi!$B$3:$E$208,3,FALSE) -> #N/A | AM15: =VLOOKUP(AD15,[1]xi!$B$3:$E$208,4,FALSE) -> #N/A | AN15: PKL
... A20: 18 | B20: 13510 | C20: '0087691184 | D20: Mochammad Rizwan Hakim | E20: XII TKJ 1 | F20: 0 | G20: 1 | H20: 2 | I20: TKJ 1 | J20: 1 | M20: 281 | N20: 14179 | P20: Helsa Amadea | Q20: =VLOOKUP(S20,'6'!$I$2:$J$33,2,FALSE) -> 10 | R20: =VLOOKUP(S20,'4'!$C$11:$F$33,2,FALSE) -> 10 | S20: =_xlfn.CONCAT(T20," ",U20) -> X TJKT 1 | T20: X | U20: TJKT 1 | V20: =VLOOKUP(P20,[1]Sheet1!$B$2:$E$393,2,FALSE) -> 0 | W20: =VLOOKUP(P20,[1]Sheet1!$B$2:$E$393,3,FALSE) -> 0 | X20: =VLOOKUP(P20,[1]Sheet1!$B$2:$E$393,4,FALSE) -> 0 | AB20: 13820 | AD20: Fabian Warzal Ahmad Zikri | AE20: 647 | AF20: =VLOOKUP(AH20,'6'!$I$2:$J$33,2,FALSE) -> 23 | AG20: =VLOOKUP(AH20,'4'!$C$11:$F$33,2,FALSE) -> 11 | AH20: =_xlfn.CONCAT(AI20," ",AJ20) -> XI TJKT 1 | AI20: XI | AJ20: TJKT 1 | AK20: =VLOOKUP(AD20,[1]xi!$B$3:$E$208,2,FALSE) -> #N/A | AL20: =VLOOKUP(AD20,[1]xi!$B$3:$E$208,3,FALSE) -> #N/A | AM20: =VLOOKUP(AD20,[1]xi!$B$3:$E$208,4,FALSE) -> #N/A | AN20: PKL
A21: 19 | B21: 13594 | C21: 76974388 | D21: Muhamad Firasa Ikhsan | E21: XII TKJ 1 | F21: 0 | G21: 0 | H21: 0 | I21: TKJ 1 | J21: 1 | M21: 282 | N21: 14180 | P21: Ikhsan Jaiz Setiawan | Q21: =VLOOKUP(S21,'6'!$I$2:$J$33,2,FALSE) -> 10 | R21: =VLOOKUP(S21,'4'!$C$11:$F$33,2,FALSE) -> 10 | S21: =_xlfn.CONCAT(T21," ",U21) -> X TJKT 1 | T21: X | U21: TJKT 1 | V21: =VLOOKUP(P21,[1]Sheet1!$B$2:$E$393,2,FALSE) -> 0 | W21: =VLOOKUP(P21,[1]Sheet1!$B$2:$E$393,3,FALSE) -> 0 | X21: =VLOOKUP(P21,[1]Sheet1!$B$2:$E$393,4,FALSE) -> 0 | AB21: 13821 | AD21: Fauzan Rahmadan Wibowo | AE21: 648 | AF21: =VLOOKUP(AH21,'6'!$I$2:$J$33,2,FALSE) -> 23 | AG21: =VLOOKUP(AH21,'4'!$C$11:$F$33,2,FALSE) -> 11 | AH21: =_xlfn.CONCAT(AI21," ",AJ21) -> XI TJKT 1 | AI21: XI | AJ21: TJKT 1 | AK21: =VLOOKUP(AD21,[1]xi!$B$3:$E$208,2,FALSE) -> #N/A | AL21: =VLOOKUP(AD21,[1]xi!$B$3:$E$208,3,FALSE) -> #N/A | AM21: =VLOOKUP(AD21,[1]xi!$B$3:$E$208,4,FALSE) -> #N/A | AN21: PKL
A22: 20 | B22: 13511 | C22: '0083759029 | D22: Putri Kurnia Ningsih | E22: XII TKJ 1 | F22: 0 | G22: 0 | H22: 1 | I22: TKJ 1 | J22: 1 | M22: 283 | N22: 14181 | P22: Iqbal Dzakwaan Yusuf Raditya | Q22: =VLOOKUP(S22,'6'!$I$2:$J$33,2,FALSE) -> 10 | R22: =VLOOKUP(S22,'4'!$C$11:$F$33,2,FALSE) -> 10 | S22: =_xlfn.CONCAT(T22," ",U22) -> X TJKT 1 | T22: X | U22: TJKT 1 | V22: =VLOOKUP(P22,[1]Sheet1!$B$2:$E$393,2,FALSE) -> 0 | W22: =VLOOKUP(P22,[1]Sheet1!$B$2:$E$393,3,FALSE) -> 0 | X22: =VLOOKUP(P22,[1]Sheet1!$B$2:$E$393,4,FALSE) -> 0 | AB22: 13822 | AD22: Febio Robert Frederico | AE22: 649 | AF22: =VLOOKUP(AH22,'6'!$I$2:$J$33,2,FALSE) -> 23 | AG22: =VLOOKUP(AH22,'4'!$C$11:$F$33,2,FALSE) -> 11 | AH22: =_xlfn.CONCAT(AI22," ",AJ22) -> XI TJKT 1 | AI22: XI | AJ22: TJKT 1 | AK22: =VLOOKUP(AD22,[1]xi!$B$3:$E$208,2,FALSE) -> #N/A | AL22: =VLOOKUP(AD22,[1]xi!$B$3:$E$208,3,FALSE) -> #N/A | AM22: =VLOOKUP(AD22,[1]xi!$B$3:$E$208,4,FALSE) -> #N/A | AN22: PKL
A23: 21 | B23: 13512 | C23: '0086305333 | D23: Rahayuning Hanif | E23: XII TKJ 1 | F23: 0 | G23: 0 | H23: 1 | I23: TKJ 1 | J23: 1 | M23: 284 | N23: 14182 | P23: Irsyad Maulana Utama | Q23: =VLOOKUP(S23,'6'!$I$2:$J$33,2,FALSE) -> 10 | R23: =VLOOKUP(S23,'4'!$C$11:$F$33,2,FALSE) -> 10 | S23: =_xlfn.CONCAT(T23," ",U23) -> X TJKT 1 | T23: X | U23: TJKT 1 | V23: =VLOOKUP(P23,[1]Sheet1!$B$2:$E$393,2,FALSE) -> 0 | W23: =VLOOKUP(P23,[1]Sheet1!$B$2:$E$393,3,FALSE) -> 0 | X23: =VLOOKUP(P23,[1]Sheet1!$B$2:$E$393,4,FALSE) -> 0 | AB23: 13928 | AD23: Gingga Amirul Muiz | AE23: 650 | AF23: =VLOOKUP(AH23,'6'!$I$2:$J$33,2,FALSE) -> 23 | AG23: =VLOOKUP(AH23,'4'!$C$11:$F$33,2,FALSE) -> 11 | AH23: =_xlfn.CONCAT(AI23," ",AJ23) -> XI TJKT 1 | AI23: XI | AJ23: TJKT 1 | AK23: =VLOOKUP(AD23,[1]xi!$B$3:$E$208,2,FALSE) -> #N/A | AL23: =VLOOKUP(AD23,[1]xi!$B$3:$E$208,3,FALSE) -> #N/A | AM23: =VLOOKUP(AD23,[1]xi!$B$3:$E$208,4,FALSE) -> #N/A | AN23: PKL
A24: 22 | B24: 13513 | C24: '0073776120 | D24: Ramandani Aas Satriyani | E24: XII TKJ 1 | F24: 1 | G24: 0 | H24: 2 | I24: TKJ 1 | J24: 1 | M24: 285 | N24: 14183 | P24: Kirana Gladis Anmarsya | Q24: =VLOOKUP(S24,'6'!$I$2:$J$33,2,FALSE) -> 10 | R24: =VLOOKUP(S24,'4'!$C$11:$F$33,2,FALSE) -> 10 | S24: =_xlfn.CONCAT(T24," ",U24) -> X TJKT 1 | T24: X | U24: TJKT 1 | V24: =VLOOKUP(P24,[1]Sheet1!$B$2:$E$393,2,FALSE) -> 0 | W24: =VLOOKUP(P24,[1]Sheet1!$B$2:$E$393,3,FALSE) -> 0 | X24: =VLOOKUP(P24,[1]Sheet1!$B$2:$E$393,4,FALSE) -> 0 | AB24: 13823 | AD24: Hilmiyahya Said | AE24: 651 | AF24: =VLOOKUP(AH24,'6'!$I$2:$J$33,2,FALSE) -> 23 | AG24: =VLOOKUP(AH24,'4'!$C$11:$F$33,2,FALSE) -> 11 | AH24: =_xlfn.CONCAT(AI24," ",AJ24) -> XI TJKT 1 | AI24: XI | AJ24: TJKT 1 | AK24: =VLOOKUP(AD24,[1]xi!$B$3:$E$208,2,FALSE) -> #N/A | AL24: =VLOOKUP(AD24,[1]xi!$B$3:$E$208,3,FALSE) -> #N/A | AM24: =VLOOKUP(AD24,[1]xi!$B$3:$E$208,4,FALSE) -> #N/A | AN24: PKL
A25: 23 | B25: 13514 | C25: '0088996550 | D25: Rayhan Danish Ghailan | E25: XII TKJ 1 | F25: 0 | G25: 0 | H25: 2 | I25: TKJ 1 | J25: 1 | M25: 286 | N25: 14184 | P25: Kirani Ariela Agustina | Q25: =VLOOKUP(S25,'6'!$I$2:$J$33,2,FALSE) -> 10 | R25: =VLOOKUP(S25,'4'!$C$11:$F$33,2,FALSE) -> 10 | S25: =_xlfn.CONCAT(T25," ",U25) -> X TJKT 1 | T25: X | U25: TJKT 1 | V25: =VLOOKUP(P25,[1]Sheet1!$B$2:$E$393,2,FALSE) -> 0 | W25: =VLOOKUP(P25,[1]Sheet1!$B$2:$E$393,3,FALSE) -> 0 | X25: =VLOOKUP(P25,[1]Sheet1!$B$2:$E$393,4,FALSE) -> 0 | AB25: 13824 | AD25: Janur Akbar Hardjo Djatmiko | AE25: 652 | AF25: =VLOOKUP(AH25,'6'!$I$2:$J$33,2,FALSE) -> 23 | AG25: =VLOOKUP(AH25,'4'!$C$11:$F$33,2,FALSE) -> 11 | AH25: =_xlfn.CONCAT(AI25," ",AJ25) -> XI TJKT 1 | AI25: XI | AJ25: TJKT 1 | AK25: =VLOOKUP(AD25,[1]xi!$B$3:$E$208,2,FALSE) -> #N/A | AL25: =VLOOKUP(AD25,[1]xi!$B$3:$E$208,3,FALSE) -> #N/A | AM25: =VLOOKUP(AD25,[1]xi!$B$3:$E$208,4,FALSE) -> #N/A | AN25: PKL
A26: 24 | B26: 13515 | C26: '0087661551 | D26: Ridho Pratama Susilo Putra | E26: XII TKJ 1 | F26: 0 | G26: 0 | H26: 0 | I26: TKJ 1 | J26: 1 | M26: 287 | N26: 14185 | P26: Krisna Bintang Timur | Q26: =VLOOKUP(S26,'6'!$I$2:$J$33,2,FALSE) -> 10 | R26: =VLOOKUP(S26,'4'!$C$11:$F$33,2,FALSE) -> 10 | S26: =_xlfn.CONCAT(T26," ",U26) -> X TJKT 1 | T26: X | U26: TJKT 1 | V26: =VLOOKUP(P26,[1]Sheet1!$B$2:$E$393,2,FALSE) -> 0 | W26: =VLOOKUP(P26,[1]Sheet1!$B$2:$E$393,3,FALSE) -> 0 | X26: =VLOOKUP(P26,[1]Sheet1!$B$2:$E$393,4,FALSE) -> 0 | AB26: 13825 | AD26: Joceline John Beno | AE26: 653 | AF26: =VLOOKUP(AH26,'6'!$I$2:$J$33,2,FALSE) -> 23 | AG26: =VLOOKUP(AH26,'4'!$C$11:$F$33,2,FALSE) -> 11 | AH26: =_xlfn.CONCAT(AI26," ",AJ26) -> XI TJKT 1 | AI26: XI | AJ26: TJKT 1 | AK26: =VLOOKUP(AD26,[1]xi!$B$3:$E$208,2,FALSE) -> #N/A | AL26: =VLOOKUP(AD26,[1]xi!$B$3:$E$208,3,FALSE) -> #N/A | AM26: =VLOOKUP(AD26,[1]xi!$B$3:$E$208,4,FALSE) -> #N/A | AN26: PKL
A27: 25 | B27: 13516 | C27: '0081137593 | D27: Rifky Arham Fahruri | E27: XII TKJ 1 | F27: 0 | G27: 0 | H27: 0 | I27: TKJ 1 | J27: 1 | M27: 288 | N27: 14186 | P27: Kukuh Wicaksono | Q27: =VLOOKUP(S27,'6'!$I$2:$J$33,2,FALSE) -> 10 | R27: =VLOOKUP(S27,'4'!$C$11:$F$33,2,FALSE) -> 10 | S27: =_xlfn.CONCAT(T27," ",U27) -> X TJKT 1 | T27: X | U27: TJKT 1 | V27: =VLOOKUP(P27,[1]Sheet1!$B$2:$E$393,2,FALSE) -> 0 | W27: =VLOOKUP(P27,[1]Sheet1!$B$2:$E$393,3,FALSE) -> 0 | X27: =VLOOKUP(P27,[1]Sheet1!$B$2:$E$393,4,FALSE) -> 0 | AB27: 13926 | AD27: Wahyu Putra Rahmadan | AE27: 654 | AF27: =VLOOKUP(AH27,'6'!$I$2:$J$33,2,FALSE) -> 23 | AG27: =VLOOKUP(AH27,'4'!$C$11:$F$33,2,FALSE) -> 11 | AH27: =_xlfn.CONCAT(AI27," ",AJ27) -> XI TJKT 1 | AI27: XI | AJ27: TJKT 1 | AK27: =VLOOKUP(AD27,[1]xi!$B$3:$E$208,2,FALSE) -> #N/A | AL27: =VLOOKUP(AD27,[1]xi!$B$3:$E$208,3,FALSE) -> #N/A | AM27: =VLOOKUP(AD27,[1]xi!$B$3:$E$208,4,FALSE) -> #N/A | AN27: PKL
A28: 26 | B28: 13517 | C28: '0077613278 | D28: Rina Jesika Oktamevia | E28: XII TKJ 1 | F28: 0 | G28: 0 | H28: 1 | I28: TKJ 1 | J28: 1 | M28: 289 | N28: 14187 | P28: Labib Nur Alam Pranata | Q28: =VLOOKUP(S28,'6'!$I$2:$J$33,2,FALSE) -> 10 | R28: =VLOOKUP(S28,'4'!$C$11:$F$33,2,FALSE) -> 10 | S28: =_xlfn.CONCAT(T28," ",U28) -> X TJKT 1 | T28: X | U28: TJKT 1 | V28: =VLOOKUP(P28,[1]Sheet1!$B$2:$E$393,2,FALSE) -> 0 | W28: =VLOOKUP(P28,[1]Sheet1!$B$2:$E$393,3,FALSE) -> 0 | X28: =VLOOKUP(P28,[1]Sheet1!$B$2:$E$393,4,FALSE) -> 1 | AB28: 13927 | AD28: Ahmad Sultan Kurniawan | AE28: 655 | AF28: =VLOOKUP(AH28,'6'!$I$2:$J$33,2,FALSE) -> 24 | AG28: =VLOOKUP(AH28,'4'!$C$11:$F$33,2,FALSE) -> 13 | AH28: =_xlfn.CONCAT(AI28," ",AJ28) -> XI TJKT 2 | AI28: XI | AJ28: TJKT 2 | AK28: =VLOOKUP(AD28,[1]xi!$B$3:$E$208,2,FALSE) -> 0 | AL28: =VLOOKUP(AD28,[1]xi!$B$3:$E$208,3,FALSE) -> 0 | AM28: =VLOOKUP(AD28,[1]xi!$B$3:$E$208,4,FALSE) -> 0 | AN28: aktif
A29: 27 | B29: 13518 | C29: '0078622601 | D29: Riski Adi Pratama | E29: XII TKJ 1 | F29: 0 | G29: 0 | H29: 3 | I29: TKJ 1 | J29: 1 | M29: 290 | N29: 14188 | P29: Lutfan Putra Khoirul Anwar | Q29: =VLOOKUP(S29,'6'!$I$2:$J$33,2,FALSE) -> 10 | R29: =VLOOKUP(S29,'4'!$C$11:$F$33,2,FALSE) -> 10 | S29: =_xlfn.CONCAT(T29," ",U29) -> X TJKT 1 | T29: X | U29: TJKT 1 | V29: =VLOOKUP(P29,[1]Sheet1!$B$2:$E$393,2,FALSE) -> 1 | W29: =VLOOKUP(P29,[1]Sheet1!$B$2:$E$393,3,FALSE) -> 0 | X29: =VLOOKUP(P29,[1]Sheet1!$B$2:$E$393,4,FALSE) -> 2 | AB29: 13826 | AD29: Karim Ikhsan Rafiki | AE29: 656 | AF29: =VLOOKUP(AH29,'6'!$I$2:$J$33,2,FALSE) -> 24 | AG29: =VLOOKUP(AH29,'4'!$C$11:$F$33,2,FALSE) -> 13 | AH29: =_xlfn.CONCAT(AI29," ",AJ29) -> XI TJKT 2 | AI29: XI | AJ29: TJKT 2 | AK29: =VLOOKUP(AD29,[1]xi!$B$3:$E$208,2,FALSE) -> 0 | AL29: =VLOOKUP(AD29,[1]xi!$B$3:$E$208,3,FALSE) -> 0 | AM29: =VLOOKUP(AD29,[1]xi!$B$3:$E$208,4,FALSE) -> 0 | AN29: aktif
A30: 28 | B30: 13519 | C30: '0089648209 | D30: Roofid Alharits Bagaskara | E30: XII TKJ 1 | F30: 0 | G30: 0 | H30: 3 | I30: TKJ 1 | J30: 1 | M30: 291 | N30: 14189 | P30: Luthfi Khoirul Ain | Q30: =VLOOKUP(S30,'6'!$I$2:$J$33,2,FALSE) -> 10 | R30: =VLOOKUP(S30,'4'!$C$11:$F$33,2,FALSE) -> 10 | S30: =_xlfn.CONCAT(T30," ",U30) -> X TJKT 1 | T30: X | U30: TJKT 1 | V30: =VLOOKUP(P30,[1]Sheet1!$B$2:$E$393,2,FALSE) -> 0 | W30: =VLOOKUP(P30,[1]Sheet1!$B$2:$E$393,3,FALSE) -> 0 | X30: =VLOOKUP(P30,[1]Sheet1!$B$2:$E$393,4,FALSE) -> 0 | AB30: 13827 | AD30: Muhamad Ridho Alkhofi | AE30: 657 | AF30: =VLOOKUP(AH30,'6'!$I$2:$J$33,2,FALSE) -> 24 | AG30: =VLOOKUP(AH30,'4'!$C$11:$F$33,2,FALSE) -> 13 | AH30: =_xlfn.CONCAT(AI30," ",AJ30) -> XI TJKT 2 | AI30: XI | AJ30: TJKT 2 | AK30: =VLOOKUP(AD30,[1]xi!$B$3:$E$208,2,FALSE) -> 0 | AL30: =VLOOKUP(AD30,[1]xi!$B$3:$E$208,3,FALSE) -> 0 | AM30: =VLOOKUP(AD30,[1]xi!$B$3:$E$208,4,FALSE) -> 0 | AN30: aktif
A31: 29 | B31: 13520 | C31: '0087482330 | D31: Siti Solekah Dwi Jayanti | E31: XII TKJ 1 | F31: 0 | G31: 0 | H31: 0 | I31: TKJ 1 | J31: 1 | M31: 292 | N31: 14190 | P31: Lyra Aisyah Zahra | Q31: =VLOOKUP(S31,'6'!$I$2:$J$33,2,FALSE) -> 10 | R31: =VLOOKUP(S31,'4'!$C$11:$F$33,2,FALSE) -> 10 | S31: =_xlfn.CONCAT(T31," ",U31) -> X TJKT 1 | T31: X | U31: TJKT 1 | V31: =VLOOKUP(P31,[1]Sheet1!$B$2:$E$393,2,FALSE) -> 1 | W31: =VLOOKUP(P31,[1]Sheet1!$B$2:$E$393,3,FALSE) -> 0 | X31: =VLOOKUP(P31,[1]Sheet1!$B$2:$E$393,4,FALSE) -> 0 | AB31: 13828 | AD31: Muhammad Ananda Akbar Fatkhurrozi | AE31: 658 | AF31: =VLOOKUP(AH31,'6'!$I$2:$J$33,2,FALSE) -> 24 | AG31: =VLOOKUP(AH31,'4'!$C$11:$F$33,2,FALSE) -> 13 | AH31: =_xlfn.CONCAT(AI31," ",AJ31) -> XI TJKT 2 | AI31: XI | AJ31: TJKT 2 | AK31: =VLOOKUP(AD31,[1]xi!$B$3:$E$208,2,FALSE) -> 0 | AL31: =VLOOKUP(AD31,[1]xi!$B$3:$E$208,3,FALSE) -> 0 | AM31: =VLOOKUP(AD31,[1]xi!$B$3:$E$208,4,FALSE) -> 2 | AN31: aktif
A32: 30 | B32: 13521 | C32: '0079675538 | D32: Umar Abdul Azis | E32: XII TKJ 1 | F32: 0 | G32: 0 | H32: 3 | I32: TKJ 1 | J32: 1 | M32: 293 | N32: 14191 | P32: Ma'ruf Vicky Aldiano Rahman | Q32: =VLOOKUP(S32,'6'!$I$2:$J$33,2,FALSE) -> 10 | R32: =VLOOKUP(S32,'4'!$C$11:$F$33,2,FALSE) -> 10 | S32: =_xlfn.CONCAT(T32," ",U32) -> X TJKT 1 | T32: X | U32: TJKT 1 | V32: =VLOOKUP(P32,[1]Sheet1!$B$2:$E$393,2,FALSE) -> 0 | W32: =VLOOKUP(P32,[1]Sheet1!$B$2:$E$393,3,FALSE) -> 0 | X32: =VLOOKUP(P32,[1]Sheet1!$B$2:$E$393,4,FALSE) -> 1 | AB32: 13829 | AD32: Muhammad Arifin | AE32: 659 | AF32: =VLOOKUP(AH32,'6'!$I$2:$J$33,2,FALSE) -> 24 | AG32: =VLOOKUP(AH32,'4'!$C$11:$F$33,2,FALSE) -> 13 | AH32: =_xlfn.CONCAT(AI32," ",AJ32) -> XI TJKT 2 | AI32: XI | AJ32: TJKT 2 | AK32: =VLOOKUP(AD32,[1]xi!$B$3:$E$208,2,FALSE) -> 0 | AL32: =VLOOKUP(AD32,[1]xi!$B$3:$E$208,3,FALSE) -> 0 | AM32: =VLOOKUP(AD32,[1]xi!$B$3:$E$208,4,FALSE) -> 0 | AN32: aktif
A33: 31 | B33: 13522 | C33: '0081462916 | D33: Wanda Nur Aini | E33: XII TKJ 1 | F33: 0 | G33: 0 | H33: 0 | I33: TKJ 1 | J33: 1 | M33: 294 | N33: 14192 | P33: Mirdawati Khoirunisa | Q33: =VLOOKUP(S33,'6'!$I$2:$J$33,2,FALSE) -> 11 | R33: =VLOOKUP(S33,'4'!$C$11:$F$33,2,FALSE) -> 12 | S33: =_xlfn.CONCAT(T33," ",U33) -> X TJKT 2 | T33: X | U33: TJKT 2 | V33: =VLOOKUP(P33,[1]Sheet1!$B$2:$E$393,2,FALSE) -> 0 | W33: =VLOOKUP(P33,[1]Sheet1!$B$2:$E$393,3,FALSE) -> 0 | X33: =VLOOKUP(P33,[1]Sheet1!$B$2:$E$393,4,FALSE) -> 0 | AB33: 13831 | AD33: Muhammad Fikri Sabiluddin | AE33: 660 | AF33: =VLOOKUP(AH33,'6'!$I$2:$J$33,2,FALSE) -> 24 | AG33: =VLOOKUP(AH33,'4'!$C$11:$F$33,2,FALSE) -> 13 | AH33: =_xlfn.CONCAT(AI33," ",AJ33) -> XI TJKT 2 | AI33: XI | AJ33: TJKT 2 | AK33: =VLOOKUP(AD33,[1]xi!$B$3:$E$208,2,FALSE) -> 0 | AL33: =VLOOKUP(AD33,[1]xi!$B$3:$E$208,3,FALSE) -> 0 | AM33: =VLOOKUP(AD33,[1]xi!$B$3:$E$208,4,FALSE) -> 0 | AN33: aktif
... A58: 56 | B58: 13324 | C58: '0084622039 | D58: Fauzan Galih Saputra | E58: XII TOI 1 | F58: 0 | G58: 0 | H58: 0 | I58: TOI 1 | J58: 2 | M58: 319 | N58: 14217 | P58: Sinu Bambang Muhlasin | Q58: =VLOOKUP(S58,'6'!$I$2:$J$33,2,FALSE) -> 11 | R58: =VLOOKUP(S58,'4'!$C$11:$F$33,2,FALSE) -> 12 | S58: =_xlfn.CONCAT(T58," ",U58) -> X TJKT 2 | T58: X | U58: TJKT 2 | V58: =VLOOKUP(P58,[1]Sheet1!$B$2:$E$393,2,FALSE) -> 0 | W58: =VLOOKUP(P58,[1]Sheet1!$B$2:$E$393,3,FALSE) -> 0 | X58: =VLOOKUP(P58,[1]Sheet1!$B$2:$E$393,4,FALSE) -> 0 | AB58: 13605 | AD58: Aroqyan Azis Khoirul Misbah | AE58: 685 | AF58: =VLOOKUP(AH58,'6'!$I$2:$J$33,2,FALSE) -> 25 | AG58: =VLOOKUP(AH58,'4'!$C$11:$F$33,2,FALSE) -> 15 | AH58: =_xlfn.CONCAT(AI58," ",AJ58) -> XI TOI 1 | AI58: XI | AJ58: TOI 1 | AK58: =VLOOKUP(AD58,[1]xi!$B$3:$E$208,2,FALSE) -> #N/A | AL58: =VLOOKUP(AD58,[1]xi!$B$3:$E$208,3,FALSE) -> #N/A | AM58: =VLOOKUP(AD58,[1]xi!$B$3:$E$208,4,FALSE) -> #N/A | AN58: PKL
A59: 57 | B59: 13325 | C59: 3081462954 | D59: Fauzi Danar Ramadhani | E59: XII TOI 2 | F59: 0 | G59: 0 | H59: 1 | I59: TOI 2 | J59: 3 | M59: 320 | N59: 14218 | P59: Virginnia Dodi Suyoto | Q59: =VLOOKUP(S59,'6'!$I$2:$J$33,2,FALSE) -> 11 | R59: =VLOOKUP(S59,'4'!$C$11:$F$33,2,FALSE) -> 12 | S59: =_xlfn.CONCAT(T59," ",U59) -> X TJKT 2 | T59: X | U59: TJKT 2 | V59: =VLOOKUP(P59,[1]Sheet1!$B$2:$E$393,2,FALSE) -> 0 | W59: =VLOOKUP(P59,[1]Sheet1!$B$2:$E$393,3,FALSE) -> 0 | X59: =VLOOKUP(P59,[1]Sheet1!$B$2:$E$393,4,FALSE) -> 0 | AB59: 13606 | AD59: Azwanirham Fahriza | AE59: 686 | AF59: =VLOOKUP(AH59,'6'!$I$2:$J$33,2,FALSE) -> 25 | AG59: =VLOOKUP(AH59,'4'!$C$11:$F$33,2,FALSE) -> 15 | AH59: =_xlfn.CONCAT(AI59," ",AJ59) -> XI TOI 1 | AI59: XI | AJ59: TOI 1 | AK59: =VLOOKUP(AD59,[1]xi!$B$3:$E$208,2,FALSE) -> #N/A | AL59: =VLOOKUP(AD59,[1]xi!$B$3:$E$208,3,FALSE) -> #N/A | AM59: =VLOOKUP(AD59,[1]xi!$B$3:$E$208,4,FALSE) -> #N/A | AN59: PKL
A60: 58 | B60: 13327 | C60: '0072550548 | D60: Gumilar Andyka Prassetyo | E60: XII TOI 2 | F60: 0 | G60: 0 | H60: 3 | I60: TOI 2 | J60: 3 | M60: 321 | N60: 14219 | P60: Wahyu Febri Pratama | Q60: =VLOOKUP(S60,'6'!$I$2:$J$33,2,FALSE) -> 11 | R60: =VLOOKUP(S60,'4'!$C$11:$F$33,2,FALSE) -> 12 | S60: =_xlfn.CONCAT(T60," ",U60) -> X TJKT 2 | T60: X | U60: TJKT 2 | V60: =VLOOKUP(P60,[1]Sheet1!$B$2:$E$393,2,FALSE) -> 0 | W60: =VLOOKUP(P60,[1]Sheet1!$B$2:$E$393,3,FALSE) -> 0 | X60: =VLOOKUP(P60,[1]Sheet1!$B$2:$E$393,4,FALSE) -> 0 | AB60: 13607 | AD60: Cenata Arya Fizziansyah | AE60: 687 | AF60: =VLOOKUP(AH60,'6'!$I$2:$J$33,2,FALSE) -> 25 | AG60: =VLOOKUP(AH60,'4'!$C$11:$F$33,2,FALSE) -> 15 | AH60: =_xlfn.CONCAT(AI60," ",AJ60) -> XI TOI 1 | AI60: XI | AJ60: TOI 1 | AK60: =VLOOKUP(AD60,[1]xi!$B$3:$E$208,2,FALSE) -> #N/A | AL60: =VLOOKUP(AD60,[1]xi!$B$3:$E$208,3,FALSE) -> #N/A | AM60: =VLOOKUP(AD60,[1]xi!$B$3:$E$208,4,FALSE) -> #N/A | AN60: PKL
A61: 59 | B61: 13328 | C61: '3076921697 | D61: Ichtiar Agiel Putra Abi Cahya | E61: XII TOI 2 | F61: 0 | G61: 0 | H61: 3 | I61: TOI 2 | J61: 3 | M61: 322 | N61: 14220 | P61: Zahro Shidiq Barokatin | Q61: =VLOOKUP(S61,'6'!$I$2:$J$33,2,FALSE) -> 11 | R61: =VLOOKUP(S61,'4'!$C$11:$F$33,2,FALSE) -> 12 | S61: =_xlfn.CONCAT(T61," ",U61) -> X TJKT 2 | T61: X | U61: TJKT 2 | V61: =VLOOKUP(P61,[1]Sheet1!$B$2:$E$393,2,FALSE) -> 0 | W61: =VLOOKUP(P61,[1]Sheet1!$B$2:$E$393,3,FALSE) -> 0 | X61: =VLOOKUP(P61,[1]Sheet1!$B$2:$E$393,4,FALSE) -> 0 | AB61: 13608 | AD61: Daffa Khoirul Annas | AE61: 688 | AF61: =VLOOKUP(AH61,'6'!$I$2:$J$33,2,FALSE) -> 25 | AG61: =VLOOKUP(AH61,'4'!$C$11:$F$33,2,FALSE) -> 15 | AH61: =_xlfn.CONCAT(AI61," ",AJ61) -> XI TOI 1 | AI61: XI | AJ61: TOI 1 | AK61: =VLOOKUP(AD61,[1]xi!$B$3:$E$208,2,FALSE) -> #N/A | AL61: =VLOOKUP(AD61,[1]xi!$B$3:$E$208,3,FALSE) -> #N/A | AM61: =VLOOKUP(AD61,[1]xi!$B$3:$E$208,4,FALSE) -> #N/A | AN61: PKL
A62: 60 | B62: 13329 | C62: '0072531718 | D62: Ihksan Nur Alamsyah | E62: XII TOI 2 | F62: 0 | G62: 0 | H62: 3 | I62: TOI 2 | J62: 3 | M62: 323 | N62: 14221 | P62: Zahrotus Syifa Nur Maharani | Q62: =VLOOKUP(S62,'6'!$I$2:$J$33,2,FALSE) -> 11 | R62: =VLOOKUP(S62,'4'!$C$11:$F$33,2,FALSE) -> 12 | S62: =_xlfn.CONCAT(T62," ",U62) -> X TJKT 2 | T62: X | U62: TJKT 2 | V62: =VLOOKUP(P62,[1]Sheet1!$B$2:$E$393,2,FALSE) -> 0 | W62: =VLOOKUP(P62,[1]Sheet1!$B$2:$E$393,3,FALSE) -> 0 | X62: =VLOOKUP(P62,[1]Sheet1!$B$2:$E$393,4,FALSE) -> 0 | AB62: 13609 | AD62: Damar Novel Eka Prahuda | AE62: 689 | AF62: =VLOOKUP(AH62,'6'!$I$2:$J$33,2,FALSE) -> 25 | AG62: =VLOOKUP(AH62,'4'!$C$11:$F$33,2,FALSE) -> 15 | AH62: =_xlfn.CONCAT(AI62," ",AJ62) -> XI TOI 1 | AI62: XI | AJ62: TOI 1 | AK62: =VLOOKUP(AD62,[1]xi!$B$3:$E$208,2,FALSE) -> #N/A | AL62: =VLOOKUP(AD62,[1]xi!$B$3:$E$208,3,FALSE) -> #N/A | AM62: =VLOOKUP(AD62,[1]xi!$B$3:$E$208,4,FALSE) -> #N/A | AN62: PKL
